Workbook

Sheet Resumo Executivo
B2: Análise Comparativa de 3 Concorrentes — SIENO, BAGATELLE e AUMA
B3: Catálogos completos anunciados no Mercado Livre · gerado a partir dos 3 arquivos enviados
B5: Indicador | C5: SIENO | D5: BAGATELLE | E5: AUMA | F5: Total (3 concorrentes)
B6: Receita (R$) | C6: =SUMIF('Dados Brutos'!$T:$T,C$5,'Dados Brutos'!$C:$C) -> 8228730 | D6: =SUMIF('Dados Brutos'!$T:$T,D$5,'Dados Brutos'!$C:$C) -> 3808650 | E6: =SUMIF('Dados Brutos'!$T:$T,E$5,'Dados Brutos'!$C:$C) -> 9294080 | F6: =SUM(C6:E6) -> 21331460
B7: Unidades vendidas | C7: =SUMIF('Dados Brutos'!$T:$T,C$5,'Dados Brutos'!$D:$D) -> 79159 | D7: =SUMIF('Dados Brutos'!$T:$T,D$5,'Dados Brutos'!$D:$D) -> 6513 | E7: =SUMIF('Dados Brutos'!$T:$T,E$5,'Dados Brutos'!$D:$D) -> 18578 | F7: =SUM(C7:E7) -> 104250
B8: Anúncios (SKUs) | C8: =COUNTIF('Dados Brutos'!$T:$T,C$5) -> 893 | D8: =COUNTIF('Dados Brutos'!$T:$T,D$5) -> 1089 | E8: =COUNTIF('Dados Brutos'!$T:$T,E$5) -> 2006 | F8: =SUM(C8:E8) -> 3988
B9: Marcas distintas | C9: =SUMIFS('Dados Brutos'!$W:$W,'Dados Brutos'!$T:$T,C$5) -> 187 | D9: =SUMIFS('Dados Brutos'!$W:$W,'Dados Brutos'!$T:$T,D$5) -> 70 | E9: =SUMIFS('Dados Brutos'!$W:$W,'Dados Brutos'!$T:$T,E$5) -> 89 | F9: 275
B11: Marcas vendidas pelos 3 concorrentes | C11: =COUNTIF('Comparativo de Marcas'!K2:K276,"Sim") -> 19
B12: Marcas sinalizadas como oportunidade* | C12: =COUNTIF('Comparativo de Marcas'!L2:L276,"Sim") -> 64
B13: Marca líder em receita combinada | C13: ='Comparativo de Marcas'!A2 -> CAROLINA HERRERA
B15: * Critério de oportunidade (heurística do Bruno)
B16: Marca com ticket médio combinado >= R$100 (faixa em que a concorrência costuma ser menor) e demanda validada (>= 100 unidades vendidas somando os 3 catálogos). É um filtro de partida — cruzar sempre com margem, fornecedor e exclusividade de marca antes de decidir.
B18: Como usar este relatório
B19: • | C19: Aba "Oportunidades": só as marcas que passam no seu critério (ticket/volume), já filtradas — sem depender de cor —, e logo abaixo os anúncios individuais dessas marcas nos 3 concorrentes, ordenados por receita.
B20: • | C20: Aba "Comparativo de Marcas": a visão completa — todas as marcas dos 3 concorrentes lado a lado, com a receita em cada um, quantos concorrentes vendem cada marca e o sinalizador de oportunidade (linhas amarelas = vendida pelos 3; linhas verdes = passa no critério).
B21: • | C21: Aba "Por Categoria": mesma base, agrupada por categoria de produto (a SIENO vende outras coisas além de perfume; BAGATELLE e AUMA são quase 100% perfumaria).
B22: • | C22: Aba "Produtos por GTIN": junta os anúncios que são o mesmo produto (mesmo código de barras), já recuperando o tamanho certo ao cruzar as variações de título — e mostra, lado a lado, o preço de cada concorrente quando o mesmo GTIN aparece em mais de um.
B23: • | C23: Aba "Dados Brutos": os 3.988 anúncios originais dos 3 concorrentes, com a coluna "Categoria" classificada automaticamente. Corrigir uma linha aqui recalcula "Comparativo de Marcas", "Por Categoria" e a lista de marcas em "Oportunidades" — a lista de produtos em "Oportunidades" é fixa e precisa ser regenerada se os dados mudarem.
B25: Limitações e observações importantes
B26: • | C26: Os títulos dos anúncios vêm truncados em 40 caracteres na exportação de origem — a classificação por categoria usa apenas esse trecho, então uma parcela cai em "Outros/Diversos" por não bater com nenhuma palavra-chave.
B27: • | C27: SIENO tem um catálogo multi-categoria (perfumaria é ~29% da receita dela); BAGATELLE e AUMA são especializadas em perfumaria — a comparação de receita entre marcas é mais direta para as marcas de perfumaria presentes nos 3.
B28: • | C28: Isso mostra o que cada concorrente vende e fatura — não a margem deles, nem se há espaço real (exclusividade de marca, nº de outros vendedores, MSRP) pra você entrar. Ponto de partida pro garimpo, não decisão final.
B29: • | C29: Os números refletem o período coberto por cada exportação enviada (não informado nos arquivos, e pode não ser o mesmo período nos 3) — comparação pontual, não uma série histórica sincronizada.

Sheet Oportunidades
A1: Marcas oportunidade (64) — ticket médio combinado ≥ R$100 e ≥100 unidades vendidas (critério do Bruno)
A2: Marca | B2: Categoria | C2: Receita SIENO (R$) | D2: Receita BAGATELLE (R$) | E2: Receita AUMA (R$) | F2: Receita Total (R$) | G2: Unidades Total | H2: Ticket Médio (R$)
A3: =IFERROR(INDEX('Comparativo de Marcas'!$A:$A,MATCH(1,'Comparativo de Marcas'!$M:$M,0)),"") -> CAROLINA HERRERA | B3: =IFERROR(INDEX('Comparativo de Marcas'!$B:$B,MATCH(1,'Comparativo de Marcas'!$M:$M,0)),"") -> Perfumaria/Colonia | C3: =IFERROR(INDEX('Comparativo de Marcas'!$C:$C,MATCH(1,'Comparativo de Marcas'!$M:$M,0)),"") -> 0 | D3: =IFERROR(INDEX('Comparativo de Marcas'!$D:$D,MATCH(1,'Comparativo de Marcas'!$M:$M,0)),"") -> 1332020 | E3: =IFERROR(INDEX('Comparativo de Marcas'!$E:$E,MATCH(1,'Comparativo de Marcas'!$M:$M,0)),"") -> 2191200 | F3: =IFERROR(INDEX('Comparativo de Marcas'!$F:$F,MATCH(1,'Comparativo de Marcas'!$M:$M,0)),"") -> 3523220 | G3: =IFERROR(INDEX('Comparativo de Marcas'!$G:$G,MATCH(1,'Comparativo de Marcas'!$M:$M,0)),"") -> 5687 | H3: =IFERROR(INDEX('Comparativo de Marcas'!$I:$I,MATCH(1,'Comparativo de Marcas'!$M:$M,0)),"") -> 619.52172
A4: =IFERROR(INDEX('Comparativo de Marcas'!$A:$A,MATCH(2,'Comparativo de Marcas'!$M:$M,0)),"") -> RABANNE | B4: =IFERROR(INDEX('Comparativo de Marcas'!$B:$B,MATCH(2,'Comparativo de Marcas'!$M:$M,0)),"") -> Perfumaria/Colonia | C4: =IFERROR(INDEX('Comparativo de Marcas'!$C:$C,MATCH(2,'Comparativo de Marcas'!$M:$M,0)),"") -> 0 | D4: =IFERROR(INDEX('Comparativo de Marcas'!$D:$D,MATCH(2,'Comparativo de Marcas'!$M:$M,0)),"") -> 921250 | E4: =IFERROR(INDEX('Comparativo de Marcas'!$E:$E,MATCH(2,'Comparativo de Marcas'!$M:$M,0)),"") -> 1517680 | F4: =IFERROR(INDEX('Comparativo de Marcas'!$F:$F,MATCH(2,'Comparativo de Marcas'!$M:$M,0)),"") -> 2438930 | G4: =IFERROR(INDEX('Comparativo de Marcas'!$G:$G,MATCH(2,'Comparativo de Marcas'!$M:$M,0)),"") -> 3685 | H4: =IFERROR(INDEX('Comparativo de Marcas'!$I:$I,MATCH(2,'Comparativo de Marcas'!$M:$M,0)),"") -> 661.85346
A5: =IFERROR(INDEX('Comparativo de Marcas'!$A:$A,MATCH(3,'Comparativo de Marcas'!$M:$M,0)),"") -> JEAN PAUL GAULTIER | B5: =IFERROR(INDEX('Comparativo de Marcas'!$B:$B,MATCH(3,'Comparativo de Marcas'!$M:$M,0)),"") -> Perfumaria/Colonia | C5: =IFERROR(INDEX('Comparativo de Marcas'!$C:$C,MATCH(3,'Comparativo de Marcas'!$M:$M,0)),"") -> 0 | D5: =IFERROR(INDEX('Comparativo de Marcas'!$D:$D,MATCH(3,'Comparativo de Marcas'!$M:$M,0)),"") -> 387830 | E5: =IFERROR(INDEX('Comparativo de Marcas'!$E:$E,MATCH(3,'Comparativo de Marcas'!$M:$M,0)),"") -> 1397570 | F5: =IFERROR(INDEX('Comparativo de Marcas'!$F:$F,MATCH(3,'Comparativo de Marcas'!$M:$M,0)),"") -> 1785400 | G5: =IFERROR(INDEX('Comparativo de Marcas'!$G:$G,MATCH(3,'Comparativo de Marcas'!$M:$M,0)),"") -> 2595 | H5: =IFERROR(INDEX('Comparativo de Marcas'!$I:$I,MATCH(3,'Comparativo de Marcas'!$M:$M,0)),"") -> 688.01541
A6: =IFERROR(INDEX('Comparativo de Marcas'!$A:$A,MATCH(4,'Comparativo de Marcas'!$M:$M,0)),"") -> YVES SAINT LAURENT | B6: =IFERROR(INDEX('Comparativo de Marcas'!$B:$B,MATCH(4,'Comparativo de Marcas'!$M:$M,0)),"") -> Perfumaria/Colonia | C6: =IFERROR(INDEX('Comparativo de Marcas'!$C:$C,MATCH(4,'Comparativo de Marcas'!$M:$M,0)),"") -> 253760 | D6: =IFERROR(INDEX('Comparativo de Marcas'!$D:$D,MATCH(4,'Comparativo de Marcas'!$M:$M,0)),"") -> 17620 | E6: =IFERROR(INDEX('Comparativo de Marcas'!$E:$E,MATCH(4,'Comparativo de Marcas'!$M:$M,0)),"") -> 521750 | F6: =IFERROR(INDEX('Comparativo de Marcas'!$F:$F,MATCH(4,'Comparativo de Marcas'!$M:$M,0)),"") -> 793130 | G6: =IFERROR(INDEX('Comparativo de Marcas'!$G:$G,MATCH(4,'Comparativo de Marcas'!$M:$M,0)),"") -> 1123 | H6: =IFERROR(INDEX('Comparativo de Marcas'!$I:$I,MATCH(4,'Comparativo de Marcas'!$M:$M,0)),"") -> 706.26002
A7: =IFERROR(INDEX('Comparativo de Marcas'!$A:$A,MATCH(5,'Comparativo de Marcas'!$M:$M,0)),"") -> DOLCE & GABBANA | B7: =IFERROR(INDEX('Comparativo de Marcas'!$B:$B,MATCH(5,'Comparativo de Marcas'!$M:$M,0)),"") -> Perfumaria/Colonia | C7: =IFERROR(INDEX('Comparativo de Marcas'!$C:$C,MATCH(5,'Comparativo de Marcas'!$M:$M,0)),"") -> 178890 | D7: =IFERROR(INDEX('Comparativo de Marcas'!$D:$D,MATCH(5,'Comparativo de Marcas'!$M:$M,0)),"") -> 99900 | E7: =IFERROR(INDEX('Comparativo de Marcas'!$E:$E,MATCH(5,'Comparativo de Marcas'!$M:$M,0)),"") -> 170460 | F7: =IFERROR(INDEX('Comparativo de Marcas'!$F:$F,MATCH(5,'Comparativo de Marcas'!$M:$M,0)),"") -> 449250 | G7: =IFERROR(INDEX('Comparativo de Marcas'!$G:$G,MATCH(5,'Comparativo de Marcas'!$M:$M,0)),"") -> 670 | H7: =IFERROR(INDEX('Comparativo de Marcas'!$I:$I,MATCH(5,'Comparativo de Marcas'!$M:$M,0)),"") -> 670.52239
A8: =IFERROR(INDEX('Comparativo de Marcas'!$A:$A,MATCH(6,'Comparativo de Marcas'!$M:$M,0)),"") -> SHISEIDO | B8: =IFERROR(INDEX('Comparativo de Marcas'!$B:$B,MATCH(6,'Comparativo de Marcas'!$M:$M,0)),"") -> Perfumaria/Colonia | C8: =IFERROR(INDEX('Comparativo de Marcas'!$C:$C,MATCH(6,'Comparativo de Marcas'!$M:$M,0)),"") -> 0 | D8: =IFERROR(INDEX('Comparativo de Marcas'!$D:$D,MATCH(6,'Comparativo de Marcas'!$M:$M,0)),"") -> 0 | E8: =IFERROR(INDEX('Comparativo de Marcas'!$E:$E,MATCH(6,'Comparativo de Marcas'!$M:$M,0)),"") -> 447230 | F8: =IFERROR(INDEX('Comparativo de Marcas'!$F:$F,MATCH(6,'Comparativo de Marcas'!$M:$M,0)),"") -> 447230 | G8: =IFERROR(INDEX('Comparativo de Marcas'!$G:$G,MATCH(6,'Comparativo de Marcas'!$M:$M,0)),"") -> 1310 | H8: =IFERROR(INDEX('Comparativo de Marcas'!$I:$I,MATCH(6,'Comparativo de Marcas'!$M:$M,0)),"") -> 341.39695
A9: =IFERROR(INDEX('Comparativo de Marcas'!$A:$A,MATCH(7,'Comparativo de Marcas'!$M:$M,0)),"") -> LANCÔME | B9: =IFERROR(INDEX('Comparativo de Marcas'!$B:$B,MATCH(7,'Comparativo de Marcas'!$M:$M,0)),"") -> Perfumaria/Colonia | C9: =IFERROR(INDEX('Comparativo de Marcas'!$C:$C,MATCH(7,'Comparativo de Marcas'!$M:$M,0)),"") -> 0 | D9: =IFERROR(INDEX('Comparativo de Marcas'!$D:$D,MATCH(7,'Comparativo de Marcas'!$M:$M,0)),"") -> 0 | E9: =IFERROR(INDEX('Comparativo de Marcas'!$E:$E,MATCH(7,'Comparativo de Marcas'!$M:$M,0)),"") -> 443410 | F9: =IFERROR(INDEX('Comparativo de Marcas'!$F:$F,MATCH(7,'Comparativo de Marcas'!$M:$M,0)),"") -> 443410 | G9: =IFERROR(INDEX('Comparativo de Marcas'!$G:$G,MATCH(7,'Comparativo de Marcas'!$M:$M,0)),"") -> 774 | H9: =IFERROR(INDEX('Comparativo de Marcas'!$I:$I,MATCH(7,'Comparativo de Marcas'!$M:$M,0)),"") -> 572.88114
A10: =IFERROR(INDEX('Comparativo de Marcas'!$A:$A,MATCH(8,'Comparativo de Marcas'!$M:$M,0)),"") -> PRADA | B10: =IFERROR(INDEX('Comparativo de Marcas'!$B:$B,MATCH(8,'Comparativo de Marcas'!$M:$M,0)),"") -> Perfumaria/Colonia | C10: =IFERROR(INDEX('Comparativo de Marcas'!$C:$C,MATCH(8,'Comparativo de Marcas'!$M:$M,0)),"") -> 33000 | D10: =IFERROR(INDEX('Comparativo de Marcas'!$D:$D,MATCH(8,'Comparativo de Marcas'!$M:$M,0)),"") -> 940 | E10: =IFERROR(INDEX('Comparativo de Marcas'!$E:$E,MATCH(8,'Comparativo de Marcas'!$M:$M,0)),"") -> 372630 | F10: =IFERROR(INDEX('Comparativo de Marcas'!$F:$F,MATCH(8,'Comparativo de Marcas'!$M:$M,0)),"") -> 406570 | G10: =IFERROR(INDEX('Comparativo de Marcas'!$G:$G,MATCH(8,'Comparativo de Marcas'!$M:$M,0)),"") -> 519 | H10: =IFERROR(INDEX('Comparativo de Marcas'!$I:$I,MATCH(8,'Comparativo de Marcas'!$M:$M,0)),"") -> 783.37187
A11: =IFERROR(INDEX('Comparativo de Marcas'!$A:$A,MATCH(9,'Comparativo de Marcas'!$M:$M,0)),"") -> ARMANI BEAUTY | B11: =IFERROR(INDEX('Comparativo de Marcas'!$B:$B,MATCH(9,'Comparativo de Marcas'!$M:$M,0)),"") -> Perfumaria/Colonia | C11: =IFERROR(INDEX('Comparativo de Marcas'!$C:$C,MATCH(9,'Comparativo de Marcas'!$M:$M,0)),"") -> 0 | D11: =IFERROR(INDEX('Comparativo de Marcas'!$D:$D,MATCH(9,'Comparativo de Marcas'!$M:$M,0)),"") -> 0 | E11: =IFERROR(INDEX('Comparativo de Marcas'!$E:$E,MATCH(9,'Comparativo de Marcas'!$M:$M,0)),"") -> 402220 | F11: =IFERROR(INDEX('Comparativo de Marcas'!$F:$F,MATCH(9,'Comparativo de Marcas'!$M:$M,0)),"") -> 402220 | G11: =IFERROR(INDEX('Comparativo de Marcas'!$G:$G,MATCH(9,'Comparativo de Marcas'!$M:$M,0)),"") -> 540 | H11: =IFERROR(INDEX('Comparativo de Marcas'!$I:$I,MATCH(9,'Comparativo de Marcas'!$M:$M,0)),"") -> 744.85185
A12: =IFERROR(INDEX('Comparativo de Marcas'!$A:$A,MATCH(10,'Comparativo de Marcas'!$M:$M,0)),"") -> MARURI | B12: =IFERROR(INDEX('Comparativo de Marcas'!$B:$B,MATCH(10,'Comparativo de Marcas'!$M:$M,0)),"") -> Pesca/Nautica | C12: =IFERROR(INDEX('Comparativo de Marcas'!$C:$C,MATCH(10,'Comparativo de Marcas'!$M:$M,0)),"") -> 344600 | D12: =IFERROR(INDEX('Comparativo de Marcas'!$D:$D,MATCH(10,'Comparativo de Marcas'!$M:$M,0)),"") -> 0 | E12: =IFERROR(INDEX('Comparativo de Marcas'!$E:$E,MATCH(10,'Comparativo de Marcas'!$M:$M,0)),"") -> 0 | F12: =IFERROR(INDEX('Comparativo de Marcas'!$F:$F,MATCH(10,'Comparativo de Marcas'!$M:$M,0)),"") -> 344600 | G12: =IFERROR(INDEX('Comparativo de Marcas'!$G:$G,MATCH(10,'Comparativo de Marcas'!$M:$M,0)),"") -> 1042 | H12: =IFERROR(INDEX('Comparativo de Marcas'!$I:$I,MATCH(10,'Comparativo de Marcas'!$M:$M,0)),"") -> 330.71017
A13: =IFERROR(INDEX('Comparativo de Marcas'!$A:$A,MATCH(11,'Comparativo de Marcas'!$M:$M,0)),"") -> SHIMANO | B13: =IFERROR(INDEX('Comparativo de Marcas'!$B:$B,MATCH(11,'Comparativo de Marcas'!$M:$M,0)),"") -> Pesca/Nautica | C13: =IFERROR(INDEX('Comparativo de Marcas'!$C:$C,MATCH(11,'Comparativo de Marcas'!$M:$M,0)),"") -> 314200 | D13: =IFERROR(INDEX('Comparativo de Marcas'!$D:$D,MATCH(11,'Comparativo de Marcas'!$M:$M,0)),"") -> 0 | E13: =IFERROR(INDEX('Comparativo de Marcas'!$E:$E,MATCH(11,'Comparativo de Marcas'!$M:$M,0)),"") -> 0 | F13: =IFERROR(INDEX('Comparativo de Marcas'!$F:$F,MATCH(11,'Comparativo de Marcas'!$M:$M,0)),"") -> 314200 | G13: =IFERROR(INDEX('Comparativo de Marcas'!$G:$G,MATCH(11,'Comparativo de Marcas'!$M:$M,0)),"") -> 1307 | H13: =IFERROR(INDEX('Comparativo de Marcas'!$I:$I,MATCH(11,'Comparativo de Marcas'!$M:$M,0)),"") -> 240.39786
A14: =IFERROR(INDEX('Comparativo de Marcas'!$A:$A,MATCH(12,'Comparativo de Marcas'!$M:$M,0)),"") -> VERSACE | B14: =IFERROR(INDEX('Comparativo de Marcas'!$B:$B,MATCH(12,'Comparativo de Marcas'!$M:$M,0)),"") -> Perfumaria/Colonia | C14: =IFERROR(INDEX('Comparativo de Marcas'!$C:$C,MATCH(12,'Comparativo de Marcas'!$M:$M,0)),"") -> 0 | D14: =IFERROR(INDEX('Comparativo de Marcas'!$D:$D,MATCH(12,'Comparativo de Marcas'!$M:$M,0)),"") -> 77180 | E14: =IFERROR(INDEX('Comparativo de Marcas'!$E:$E,MATCH(12,'Comparativo de Marcas'!$M:$M,0)),"") -> 235620 | F14: =IFERROR(INDEX('Comparativo de Marcas'!$F:$F,MATCH(12,'Comparativo de Marcas'!$M:$M,0)),"") -> 312800 | G14: =IFERROR(INDEX('Comparativo de Marcas'!$G:$G,MATCH(12,'Comparativo de Marcas'!$M:$M,0)),"") -> 534 | H14: =IFERROR(INDEX('Comparativo de Marcas'!$I:$I,MATCH(12,'Comparativo de Marcas'!$M:$M,0)),"") -> 585.76779
A15: =IFERROR(INDEX('Comparativo de Marcas'!$A:$A,MATCH(13,'Comparativo de Marcas'!$M:$M,0)),"") -> WELLA | B15: =IFERROR(INDEX('Comparativo de Marcas'!$B:$B,MATCH(13,'Comparativo de Marcas'!$M:$M,0)),"") -> Perfumaria/Colonia | C15: =IFERROR(INDEX('Comparativo de Marcas'!$C:$C,MATCH(13,'Comparativo de Marcas'!$M:$M,0)),"") -> 0 | D15: =IFERROR(INDEX('Comparativo de Marcas'!$D:$D,MATCH(13,'Comparativo de Marcas'!$M:$M,0)),"") -> 0 | E15: =IFERROR(INDEX('Comparativo de Marcas'!$E:$E,MATCH(13,'Comparativo de Marcas'!$M:$M,0)),"") -> 233560 | F15: =IFERROR(INDEX('Comparativo de Marcas'!$F:$F,MATCH(13,'Comparativo de Marcas'!$M:$M,0)),"") -> 233560 | G15: =IFERROR(INDEX('Comparativo de Marcas'!$G:$G,MATCH(13,'Comparativo de Marcas'!$M:$M,0)),"") -> 1501 | H15: =IFERROR(INDEX('Comparativo de Marcas'!$I:$I,MATCH(13,'Comparativo de Marcas'!$M:$M,0)),"") -> 155.60293
A16: =IFERROR(INDEX('Comparativo de Marcas'!$A:$A,MATCH(14,'Comparativo de Marcas'!$M:$M,0)),"") -> HUGO BOSS | B16: =IFERROR(INDEX('Comparativo de Marcas'!$B:$B,MATCH(14,'Comparativo de Marcas'!$M:$M,0)),"") -> Perfumaria/Colonia | C16: =IFERROR(INDEX('Comparativo de Marcas'!$C:$C,MATCH(14,'Comparativo de Marcas'!$M:$M,0)),"") -> 85500 | D16: =IFERROR(INDEX('Comparativo de Marcas'!$D:$D,MATCH(14,'Comparativo de Marcas'!$M:$M,0)),"") -> 49190 | E16: =IFERROR(INDEX('Comparativo de Marcas'!$E:$E,MATCH(14,'Comparativo de Marcas'!$M:$M,0)),"") -> 76360 | F16: =IFERROR(INDEX('Comparativo de Marcas'!$F:$F,MATCH(14,'Comparativo de Marcas'!$M:$M,0)),"") -> 211050 | G16: =IFERROR(INDEX('Comparativo de Marcas'!$G:$G,MATCH(14,'Comparativo de Marcas'!$M:$M,0)),"") -> 426 | H16: =IFERROR(INDEX('Comparativo de Marcas'!$I:$I,MATCH(14,'Comparativo de Marcas'!$M:$M,0)),"") -> 495.42254
A17: =IFERROR(INDEX('Comparativo de Marcas'!$A:$A,MATCH(15,'Comparativo de Marcas'!$M:$M,0)),"") -> MARINE SPORTS | B17: =IFERROR(INDEX('Comparativo de Marcas'!$B:$B,MATCH(15,'Comparativo de Marcas'!$M:$M,0)),"") -> Pesca/Nautica | C17: =IFERROR(INDEX('Comparativo de Marcas'!$C:$C,MATCH(15,'Comparativo de Marcas'!$M:$M,0)),"") -> 207870 | D17: =IFERROR(INDEX('Comparativo de Marcas'!$D:$D,MATCH(15,'Comparativo de Marcas'!$M:$M,0)),"") -> 0 | E17: =IFERROR(INDEX('Comparativo de Marcas'!$E:$E,MATCH(15,'Comparativo de Marcas'!$M:$M,0)),"") -> 0 | F17: =IFERROR(INDEX('Comparativo de Marcas'!$F:$F,MATCH(15,'Comparativo de Marcas'!$M:$M,0)),"") -> 207870 | G17: =IFERROR(INDEX('Comparativo de Marcas'!$G:$G,MATCH(15,'Comparativo de Marcas'!$M:$M,0)),"") -> 1351 | H17: =IFERROR(INDEX('Comparativo de Marcas'!$I:$I,MATCH(15,'Comparativo de Marcas'!$M:$M,0)),"") -> 153.8638
A18: =IFERROR(INDEX('Comparativo de Marcas'!$A:$A,MATCH(16,'Comparativo de Marcas'!$M:$M,0)),"") -> INVICTUS | B18: =IFERROR(INDEX('Comparativo de Marcas'!$B:$B,MATCH(16,'Comparativo de Marcas'!$M:$M,0)),"") -> Tatico/Outdoor | C18: =IFERROR(INDEX('Comparativo de Marcas'!$C:$C,MATCH(16,'Comparativo de Marcas'!$M:$M,0)),"") -> 202830 | D18: =IFERROR(INDEX('Comparativo de Marcas'!$D:$D,MATCH(16,'Comparativo de Marcas'!$M:$M,0)),"") -> 0 | E18: =IFERROR(INDEX('Comparativo de Marcas'!$E:$E,MATCH(16,'Comparativo de Marcas'!$M:$M,0)),"") -> 0 | F18: =IFERROR(INDEX('Comparativo de Marcas'!$F:$F,MATCH(16,'Comparativo de Marcas'!$M:$M,0)),"") -> 202830 | G18: =IFERROR(INDEX('Comparativo de Marcas'!$G:$G,MATCH(16,'Comparativo de Marcas'!$M:$M,0)),"") -> 1208 | H18: =IFERROR(INDEX('Comparativo de Marcas'!$I:$I,MATCH(16,'Comparativo de Marcas'!$M:$M,0)),"") -> 167.90563
A19: =IFERROR(INDEX('Comparativo de Marcas'!$A:$A,MATCH(17,'Comparativo de Marcas'!$M:$M,0)),"") -> CALVIN KLEIN | B19: =IFERROR(INDEX('Comparativo de Marcas'!$B:$B,MATCH(17,'Comparativo de Marcas'!$M:$M,0)),"") -> Perfumaria/Colonia | C19: =IFERROR(INDEX('Comparativo de Marcas'!$C:$C,MATCH(17,'Comparativo de Marcas'!$M:$M,0)),"") -> 65700 | D19: =IFERROR(INDEX('Comparativo de Marcas'!$D:$D,MATCH(17,'Comparativo de Marcas'!$M:$M,0)),"") -> 128030 | E19: =IFERROR(INDEX('Comparativo de Marcas'!$E:$E,MATCH(17,'Comparativo de Marcas'!$M:$M,0)),"") -> 5280 | F19: =IFERROR(INDEX('Comparativo de Marcas'!$F:$F,MATCH(17,'Comparativo de Marcas'!$M:$M,0)),"") -> 199010 | G19: =IFERROR(INDEX('Comparativo de Marcas'!$G:$G,MATCH(17,'Comparativo de Marcas'!$M:$M,0)),"") -> 507 | H19: =IFERROR(INDEX('Comparativo de Marcas'!$I:$I,MATCH(17,'Comparativo de Marcas'!$M:$M,0)),"") -> 392.52465
A20: =IFERROR(INDEX('Comparativo de Marcas'!$A:$A,MATCH(18,'Comparativo de Marcas'!$M:$M,0)),"") -> BESTFER | B20: =IFERROR(INDEX('Comparativo de Marcas'!$B:$B,MATCH(18,'Comparativo de Marcas'!$M:$M,0)),"") -> Outros/Diversos | C20: =IFERROR(INDEX('Comparativo de Marcas'!$C:$C,MATCH(18,'Comparativo de Marcas'!$M:$M,0)),"") -> 196270 | D20: =IFERROR(INDEX('Comparativo de Marcas'!$D:$D,MATCH(18,'Comparativo de Marcas'!$M:$M,0)),"") -> 0 | E20: =IFERROR(INDEX('Comparativo de Marcas'!$E:$E,MATCH(18,'Comparativo de Marcas'!$M:$M,0)),"") -> 0 | F20: =IFERROR(INDEX('Comparativo de Marcas'!$F:$F,MATCH(18,'Comparativo de Marcas'!$M:$M,0)),"") -> 196270 | G20: =IFERROR(INDEX('Comparativo de Marcas'!$G:$G,MATCH(18,'Comparativo de Marcas'!$M:$M,0)),"") -> 1905 | H20: =IFERROR(INDEX('Comparativo de Marcas'!$I:$I,MATCH(18,'Comparativo de Marcas'!$M:$M,0)),"") -> 103.02887
A21: =IFERROR(INDEX('Comparativo de Marcas'!$A:$A,MATCH(19,'Comparativo de Marcas'!$M:$M,0)),"") -> GIORGIO ARMANI | B21: =IFERROR(INDEX('Comparativo de Marcas'!$B:$B,MATCH(19,'Comparativo de Marcas'!$M:$M,0)),"") -> Perfumaria/Colonia | C21: =IFERROR(INDEX('Comparativo de Marcas'!$C:$C,MATCH(19,'Comparativo de Marcas'!$M:$M,0)),"") -> 0 | D21: =IFERROR(INDEX('Comparativo de Marcas'!$D:$D,MATCH(19,'Comparativo de Marcas'!$M:$M,0)),"") -> 0 | E21: =IFERROR(INDEX('Comparativo de Marcas'!$E:$E,MATCH(19,'Comparativo de Marcas'!$M:$M,0)),"") -> 193570 | F21: =IFERROR(INDEX('Comparativo de Marcas'!$F:$F,MATCH(19,'Comparativo de Marcas'!$M:$M,0)),"") -> 193570 | G21: =IFERROR(INDEX('Comparativo de Marcas'!$G:$G,MATCH(19,'Comparativo de Marcas'!$M:$M,0)),"") -> 270 | H21: =IFERROR(INDEX('Comparativo de Marcas'!$I:$I,MATCH(19,'Comparativo de Marcas'!$M:$M,0)),"") -> 716.92593
A22: =IFERROR(INDEX('Comparativo de Marcas'!$A:$A,MATCH(20,'Comparativo de Marcas'!$M:$M,0)),"") -> JACQUES BOGART | B22: =IFERROR(INDEX('Comparativo de Marcas'!$B:$B,MATCH(20,'Comparativo de Marcas'!$M:$M,0)),"") -> Perfumaria/Colonia | C22: =IFERROR(INDEX('Comparativo de Marcas'!$C:$C,MATCH(20,'Comparativo de Marcas'!$M:$M,0)),"") -> 64100 | D22: =IFERROR(INDEX('Comparativo de Marcas'!$D:$D,MATCH(20,'Comparativo de Marcas'!$M:$M,0)),"") -> 128360 | E22: =IFERROR(INDEX('Comparativo de Marcas'!$E:$E,MATCH(20,'Comparativo de Marcas'!$M:$M,0)),"") -> 0 | F22: =IFERROR(INDEX('Comparativo de Marcas'!$F:$F,MATCH(20,'Comparativo de Marcas'!$M:$M,0)),"") -> 192460 | G22: =IFERROR(INDEX('Comparativo de Marcas'!$G:$G,MATCH(20,'Comparativo de Marcas'!$M:$M,0)),"") -> 635 | H22: =IFERROR(INDEX('Comparativo de Marcas'!$I:$I,MATCH(20,'Comparativo de Marcas'!$M:$M,0)),"") -> 303.08661
A23: =IFERROR(INDEX('Comparativo de Marcas'!$A:$A,MATCH(21,'Comparativo de Marcas'!$M:$M,0)),"") -> DEWALT | B23: =IFERROR(INDEX('Comparativo de Marcas'!$B:$B,MATCH(21,'Comparativo de Marcas'!$M:$M,0)),"") -> Ferramentas | C23: =IFERROR(INDEX('Comparativo de Marcas'!$C:$C,MATCH(21,'Comparativo de Marcas'!$M:$M,0)),"") -> 190000 | D23: =IFERROR(INDEX('Comparativo de Marcas'!$D:$D,MATCH(21,'Comparativo de Marcas'!$M:$M,0)),"") -> 0 | E23: =IFERROR(INDEX('Comparativo de Marcas'!$E:$E,MATCH(21,'Comparativo de Marcas'!$M:$M,0)),"") -> 0 | F23: =IFERROR(INDEX('Comparativo de Marcas'!$F:$F,MATCH(21,'Comparativo de Marcas'!$M:$M,0)),"") -> 190000 | G23: =IFERROR(INDEX('Comparativo de Marcas'!$G:$G,MATCH(21,'Comparativo de Marcas'!$M:$M,0)),"") -> 218 | H23: =IFERROR(INDEX('Comparativo de Marcas'!$I:$I,MATCH(21,'Comparativo de Marcas'!$M:$M,0)),"") -> 871.55963
A24: =IFERROR(INDEX('Comparativo de Marcas'!$A:$A,MATCH(22,'Comparativo de Marcas'!$M:$M,0)),"") -> CHLOÉ | B24: =IFERROR(INDEX('Comparativo de Marcas'!$B:$B,MATCH(22,'Comparativo de Marcas'!$M:$M,0)),"") -> Perfumaria/Colonia | C24: =IFERROR(INDEX('Comparativo de Marcas'!$C:$C,MATCH(22,'Comparativo de Marcas'!$M:$M,0)),"") -> 22240 | D24: =IFERROR(INDEX('Comparativo de Marcas'!$D:$D,MATCH(22,'Comparativo de Marcas'!$M:$M,0)),"") -> 86960 | E24: =IFERROR(INDEX('Comparativo de Marcas'!$E:$E,MATCH(22,'Comparativo de Marcas'!$M:$M,0)),"") -> 60830 | F24: =IFERROR(INDEX('Comparativo de Marcas'!$F:$F,MATCH(22,'Comparativo de Marcas'!$M:$M,0)),"") -> 170030 | G24: =IFERROR(INDEX('Comparativo de Marcas'!$G:$G,MATCH(22,'Comparativo de Marcas'!$M:$M,0)),"") -> 267 | H24: =IFERROR(INDEX('Comparativo de Marcas'!$I:$I,MATCH(22,'Comparativo de Marcas'!$M:$M,0)),"") -> 636.81648
A25: =IFERROR(INDEX('Comparativo de Marcas'!$A:$A,MATCH(23,'Comparativo de Marcas'!$M:$M,0)),"") -> BURBERRY | B25: =IFERROR(INDEX('Comparativo de Marcas'!$B:$B,MATCH(23,'Comparativo de Marcas'!$M:$M,0)),"") -> Perfumaria/Colonia | C25: =IFERROR(INDEX('Comparativo de Marcas'!$C:$C,MATCH(23,'Comparativo de Marcas'!$M:$M,0)),"") -> 33700 | D25: =IFERROR(INDEX('Comparativo de Marcas'!$D:$D,MATCH(23,'Comparativo de Marcas'!$M:$M,0)),"") -> 5390 | E25: =IFERROR(INDEX('Comparativo de Marcas'!$E:$E,MATCH(23,'Comparativo de Marcas'!$M:$M,0)),"") -> 100410 | F25: =IFERROR(INDEX('Comparativo de Marcas'!$F:$F,MATCH(23,'Comparativo de Marcas'!$M:$M,0)),"") -> 139500 | G25: =IFERROR(INDEX('Comparativo de Marcas'!$G:$G,MATCH(23,'Comparativo de Marcas'!$M:$M,0)),"") -> 238 | H25: =IFERROR(INDEX('Comparativo de Marcas'!$I:$I,MATCH(23,'Comparativo de Marcas'!$M:$M,0)),"") -> 586.13445
A26: =IFERROR(INDEX('Comparativo de Marcas'!$A:$A,MATCH(24,'Comparativo de Marcas'!$M:$M,0)),"") -> BANDERAS | B26: =IFERROR(INDEX('Comparativo de Marcas'!$B:$B,MATCH(24,'Comparativo de Marcas'!$M:$M,0)),"") -> Perfumaria/Colonia | C26: =IFERROR(INDEX('Comparativo de Marcas'!$C:$C,MATCH(24,'Comparativo de Marcas'!$M:$M,0)),"") -> 0 | D26: =IFERROR(INDEX('Comparativo de Marcas'!$D:$D,MATCH(24,'Comparativo de Marcas'!$M:$M,0)),"") -> 17780 | E26: =IFERROR(INDEX('Comparativo de Marcas'!$E:$E,MATCH(24,'Comparativo de Marcas'!$M:$M,0)),"") -> 113580 | F26: =IFERROR(INDEX('Comparativo de Marcas'!$F:$F,MATCH(24,'Comparativo de Marcas'!$M:$M,0)),"") -> 131360 | G26: =IFERROR(INDEX('Comparativo de Marcas'!$G:$G,MATCH(24,'Comparativo de Marcas'!$M:$M,0)),"") -> 653 | H26: =IFERROR(INDEX('Comparativo de Marcas'!$I:$I,MATCH(24,'Comparativo de Marcas'!$M:$M,0)),"") -> 201.16386
A27: =IFERROR(INDEX('Comparativo de Marcas'!$A:$A,MATCH(25,'Comparativo de Marcas'!$M:$M,0)),"") -> NAUTICA | B27: =IFERROR(INDEX('Comparativo de Marcas'!$B:$B,MATCH(25,'Comparativo de Marcas'!$M:$M,0)),"") -> Perfumaria/Colonia | C27: =IFERROR(INDEX('Comparativo de Marcas'!$C:$C,MATCH(25,'Comparativo de Marcas'!$M:$M,0)),"") -> 114510 | D27: =IFERROR(INDEX('Comparativo de Marcas'!$D:$D,MATCH(25,'Comparativo de Marcas'!$M:$M,0)),"") -> 7270 | E27: =IFERROR(INDEX('Comparativo de Marcas'!$E:$E,MATCH(25,'Comparativo de Marcas'!$M:$M,0)),"") -> 7260 | F27: =IFERROR(INDEX('Comparativo de Marcas'!$F:$F,MATCH(25,'Comparativo de Marcas'!$M:$M,0)),"") -> 129040 | G27: =IFERROR(INDEX('Comparativo de Marcas'!$G:$G,MATCH(25,'Comparativo de Marcas'!$M:$M,0)),"") -> 1224 | H27: =IFERROR(INDEX('Comparativo de Marcas'!$I:$I,MATCH(25,'Comparativo de Marcas'!$M:$M,0)),"") -> 105.42484
A28: =IFERROR(INDEX('Comparativo de Marcas'!$A:$A,MATCH(26,'Comparativo de Marcas'!$M:$M,0)),"") -> MAHOGANY | B28: =IFERROR(INDEX('Comparativo de Marcas'!$B:$B,MATCH(26,'Comparativo de Marcas'!$M:$M,0)),"") -> Perfumaria/Colonia | C28: =IFERROR(INDEX('Comparativo de Marcas'!$C:$C,MATCH(26,'Comparativo de Marcas'!$M:$M,0)),"") -> 0 | D28: =IFERROR(INDEX('Comparativo de Marcas'!$D:$D,MATCH(26,'Comparativo de Marcas'!$M:$M,0)),"") -> 0 | E28: =IFERROR(INDEX('Comparativo de Marcas'!$E:$E,MATCH(26,'Comparativo de Marcas'!$M:$M,0)),"") -> 114270 | F28: =IFERROR(INDEX('Comparativo de Marcas'!$F:$F,MATCH(26,'Comparativo de Marcas'!$M:$M,0)),"") -> 114270 | G28: =IFERROR(INDEX('Comparativo de Marcas'!$G:$G,MATCH(26,'Comparativo de Marcas'!$M:$M,0)),"") -> 807 | H28: =IFERROR(INDEX('Comparativo de Marcas'!$I:$I,MATCH(26,'Comparativo de Marcas'!$M:$M,0)),"") -> 141.59851
A29: =IFERROR(INDEX('Comparativo de Marcas'!$A:$A,MATCH(27,'Comparativo de Marcas'!$M:$M,0)),"") -> GUCCI | B29: =IFERROR(INDEX('Comparativo de Marcas'!$B:$B,MATCH(27,'Comparativo de Marcas'!$M:$M,0)),"") -> Perfumaria/Colonia | C29: =IFERROR(INDEX('Comparativo de Marcas'!$C:$C,MATCH(27,'Comparativo de Marcas'!$M:$M,0)),"") -> 0 | D29: =IFERROR(INDEX('Comparativo de Marcas'!$D:$D,MATCH(27,'Comparativo de Marcas'!$M:$M,0)),"") -> 29140 | E29: =IFERROR(INDEX('Comparativo de Marcas'!$E:$E,MATCH(27,'Comparativo de Marcas'!$M:$M,0)),"") -> 85100 | F29: =IFERROR(INDEX('Comparativo de Marcas'!$F:$F,MATCH(27,'Comparativo de Marcas'!$M:$M,0)),"") -> 114240 | G29: =IFERROR(INDEX('Comparativo de Marcas'!$G:$G,MATCH(27,'Comparativo de Marcas'!$M:$M,0)),"") -> 144 | H29: =IFERROR(INDEX('Comparativo de Marcas'!$I:$I,MATCH(27,'Comparativo de Marcas'!$M:$M,0)),"") -> 793.33333
A30: =IFERROR(INDEX('Comparativo de Marcas'!$A:$A,MATCH(28,'Comparativo de Marcas'!$M:$M,0)),"") -> AZZARO | B30: =IFERROR(INDEX('Comparativo de Marcas'!$B:$B,MATCH(28,'Comparativo de Marcas'!$M:$M,0)),"") -> Perfumaria/Colonia | C30: =IFERROR(INDEX('Comparativo de Marcas'!$C:$C,MATCH(28,'Comparativo de Marcas'!$M:$M,0)),"") -> 67300 | D30: =IFERROR(INDEX('Comparativo de Marcas'!$D:$D,MATCH(28,'Comparativo de Marcas'!$M:$M,0)),"") -> 0 | E30: =IFERROR(INDEX('Comparativo de Marcas'!$E:$E,MATCH(28,'Comparativo de Marcas'!$M:$M,0)),"") -> 46690 | F30: =IFERROR(INDEX('Comparativo de Marcas'!$F:$F,MATCH(28,'Comparativo de Marcas'!$M:$M,0)),"") -> 113990 | G30: =IFERROR(INDEX('Comparativo de Marcas'!$G:$G,MATCH(28,'Comparativo de Marcas'!$M:$M,0)),"") -> 297 | H30: =IFERROR(INDEX('Comparativo de Marcas'!$I:$I,MATCH(28,'Comparativo de Marcas'!$M:$M,0)),"") -> 383.80471
A31: =IFERROR(INDEX('Comparativo de Marcas'!$A:$A,MATCH(29,'Comparativo de Marcas'!$M:$M,0)),"") -> MAIS - GTECH | B31: =IFERROR(INDEX('Comparativo de Marcas'!$B:$B,MATCH(29,'Comparativo de Marcas'!$M:$M,0)),"") -> Saude/Bem-estar | C31: =IFERROR(INDEX('Comparativo de Marcas'!$C:$C,MATCH(29,'Comparativo de Marcas'!$M:$M,0)),"") -> 110000 | D31: =IFERROR(INDEX('Comparativo de Marcas'!$D:$D,MATCH(29,'Comparativo de Marcas'!$M:$M,0)),"") -> 0 | E31: =IFERROR(INDEX('Comparativo de Marcas'!$E:$E,MATCH(29,'Comparativo de Marcas'!$M:$M,0)),"") -> 0 | F31: =IFERROR(INDEX('Comparativo de Marcas'!$F:$F,MATCH(29,'Comparativo de Marcas'!$M:$M,0)),"") -> 110000 | G31: =IFERROR(INDEX('Comparativo de Marcas'!$G:$G,MATCH(29,'Comparativo de Marcas'!$M:$M,0)),"") -> 820 | H31: =IFERROR(INDEX('Comparativo de Marcas'!$I:$I,MATCH(29,'Comparativo de Marcas'!$M:$M,0)),"") -> 134.14634
A32: =IFERROR(INDEX('Comparativo de Marcas'!$A:$A,MATCH(30,'Comparativo de Marcas'!$M:$M,0)),"") -> MERCEDES-BENZ | B32: =IFERROR(INDEX('Comparativo de Marcas'!$B:$B,MATCH(30,'Comparativo de Marcas'!$M:$M,0)),"") -> Perfumaria/Colonia | C32: =IFERROR(INDEX('Comparativo de Marcas'!$C:$C,MATCH(30,'Comparativo de Marcas'!$M:$M,0)),"") -> 98400 | D32: =IFERROR(INDEX('Comparativo de Marcas'!$D:$D,MATCH(30,'Comparativo de Marcas'!$M:$M,0)),"") -> 10310 | E32: =IFERROR(INDEX('Comparativo de Marcas'!$E:$E,MATCH(30,'Comparativo de Marcas'!$M:$M,0)),"") -> 0 | F32: =IFERROR(INDEX('Comparativo de Marcas'!$F:$F,MATCH(30,'Comparativo de Marcas'!$M:$M,0)),"") -> 108710 | G32: =IFERROR(INDEX('Comparativo de Marcas'!$G:$G,MATCH(30,'Comparativo de Marcas'!$M:$M,0)),"") -> 340 | H32: =IFERROR(INDEX('Comparativo de Marcas'!$I:$I,MATCH(30,'Comparativo de Marcas'!$M:$M,0)),"") -> 319.73529
A33: =IFERROR(INDEX('Comparativo de Marcas'!$A:$A,MATCH(31,'Comparativo de Marcas'!$M:$M,0)),"") -> ADA TINA ITALY | B33: =IFERROR(INDEX('Comparativo de Marcas'!$B:$B,MATCH(31,'Comparativo de Marcas'!$M:$M,0)),"") -> Cosmeticos/Skincare | C33: =IFERROR(INDEX('Comparativo de Marcas'!$C:$C,MATCH(31,'Comparativo de Marcas'!$M:$M,0)),"") -> 102490 | D33: =IFERROR(INDEX('Comparativo de Marcas'!$D:$D,MATCH(31,'Comparativo de Marcas'!$M:$M,0)),"") -> 0 | E33: =IFERROR(INDEX('Comparativo de Marcas'!$E:$E,MATCH(31,'Comparativo de Marcas'!$M:$M,0)),"") -> 0 | F33: =IFERROR(INDEX('Comparativo de Marcas'!$F:$F,MATCH(31,'Comparativo de Marcas'!$M:$M,0)),"") -> 102490 | G33: =IFERROR(INDEX('Comparativo de Marcas'!$G:$G,MATCH(31,'Comparativo de Marcas'!$M:$M,0)),"") -> 859 | H33: =IFERROR(INDEX('Comparativo de Marcas'!$I:$I,MATCH(31,'Comparativo de Marcas'!$M:$M,0)),"") -> 119.31315
A34: =IFERROR(INDEX('Comparativo de Marcas'!$A:$A,MATCH(32,'Comparativo de Marcas'!$M:$M,0)),"") -> BRITNEY SPEARS | B34: =IFERROR(INDEX('Comparativo de Marcas'!$B:$B,MATCH(32,'Comparativo de Marcas'!$M:$M,0)),"") -> Perfumaria/Colonia | C34: =IFERROR(INDEX('Comparativo de Marcas'!$C:$C,MATCH(32,'Comparativo de Marcas'!$M:$M,0)),"") -> 97000 | D34: =IFERROR(INDEX('Comparativo de Marcas'!$D:$D,MATCH(32,'Comparativo de Marcas'!$M:$M,0)),"") -> 2880 | E34: =IFERROR(INDEX('Comparativo de Marcas'!$E:$E,MATCH(32,'Comparativo de Marcas'!$M:$M,0)),"") -> 570 | F34: =IFERROR(INDEX('Comparativo de Marcas'!$F:$F,MATCH(32,'Comparativo de Marcas'!$M:$M,0)),"") -> 100450 | G34: =IFERROR(INDEX('Comparativo de Marcas'!$G:$G,MATCH(32,'Comparativo de Marcas'!$M:$M,0)),"") -> 514 | H34: =IFERROR(INDEX('Comparativo de Marcas'!$I:$I,MATCH(32,'Comparativo de Marcas'!$M:$M,0)),"") -> 195.42802
A35: =IFERROR(INDEX('Comparativo de Marcas'!$A:$A,MATCH(33,'Comparativo de Marcas'!$M:$M,0)),"") -> KOMECO | B35: =IFERROR(INDEX('Comparativo de Marcas'!$B:$B,MATCH(33,'Comparativo de Marcas'!$M:$M,0)),"") -> Casa/Eletrodomesticos | C35: =IFERROR(INDEX('Comparativo de Marcas'!$C:$C,MATCH(33,'Comparativo de Marcas'!$M:$M,0)),"") -> 98500 | D35: =IFERROR(INDEX('Comparativo de Marcas'!$D:$D,MATCH(33,'Comparativo de Marcas'!$M:$M,0)),"") -> 0 | E35: =IFERROR(INDEX('Comparativo de Marcas'!$E:$E,MATCH(33,'Comparativo de Marcas'!$M:$M,0)),"") -> 0 | F35: =IFERROR(INDEX('Comparativo de Marcas'!$F:$F,MATCH(33,'Comparativo de Marcas'!$M:$M,0)),"") -> 98500 | G35: =IFERROR(INDEX('Comparativo de Marcas'!$G:$G,MATCH(33,'Comparativo de Marcas'!$M:$M,0)),"") -> 186 | H35: =IFERROR(INDEX('Comparativo de Marcas'!$I:$I,MATCH(33,'Comparativo de Marcas'!$M:$M,0)),"") -> 529.56989
A36: =IFERROR(INDEX('Comparativo de Marcas'!$A:$A,MATCH(34,'Comparativo de Marcas'!$M:$M,0)),"") -> RALPH LAUREN | B36: =IFERROR(INDEX('Comparativo de Marcas'!$B:$B,MATCH(34,'Comparativo de Marcas'!$M:$M,0)),"") -> Perfumaria/Colonia | C36: =IFERROR(INDEX('Comparativo de Marcas'!$C:$C,MATCH(34,'Comparativo de Marcas'!$M:$M,0)),"") -> 0 | D36: =IFERROR(INDEX('Comparativo de Marcas'!$D:$D,MATCH(34,'Comparativo de Marcas'!$M:$M,0)),"") -> 0 | E36: =IFERROR(INDEX('Comparativo de Marcas'!$E:$E,MATCH(34,'Comparativo de Marcas'!$M:$M,0)),"") -> 88440 | F36: =IFERROR(INDEX('Comparativo de Marcas'!$F:$F,MATCH(34,'Comparativo de Marcas'!$M:$M,0)),"") -> 88440 | G36: =IFERROR(INDEX('Comparativo de Marcas'!$G:$G,MATCH(34,'Comparativo de Marcas'!$M:$M,0)),"") -> 125 | H36: =IFERROR(INDEX('Comparativo de Marcas'!$I:$I,MATCH(34,'Comparativo de Marcas'!$M:$M,0)),"") -> 707.52
A37: =IFERROR(INDEX('Comparativo de Marcas'!$A:$A,MATCH(35,'Comparativo de Marcas'!$M:$M,0)),"") -> SOFT99 | B37: =IFERROR(INDEX('Comparativo de Marcas'!$B:$B,MATCH(35,'Comparativo de Marcas'!$M:$M,0)),"") -> Automotivo | C37: =IFERROR(INDEX('Comparativo de Marcas'!$C:$C,MATCH(35,'Comparativo de Marcas'!$M:$M,0)),"") -> 86100 | D37: =IFERROR(INDEX('Comparativo de Marcas'!$D:$D,MATCH(35,'Comparativo de Marcas'!$M:$M,0)),"") -> 0 | E37: =IFERROR(INDEX('Comparativo de Marcas'!$E:$E,MATCH(35,'Comparativo de Marcas'!$M:$M,0)),"") -> 0 | F37: =IFERROR(INDEX('Comparativo de Marcas'!$F:$F,MATCH(35,'Comparativo de Marcas'!$M:$M,0)),"") -> 86100 | G37: =IFERROR(INDEX('Comparativo de Marcas'!$G:$G,MATCH(35,'Comparativo de Marcas'!$M:$M,0)),"") -> 816 | H37: =IFERROR(INDEX('Comparativo de Marcas'!$I:$I,MATCH(35,'Comparativo de Marcas'!$M:$M,0)),"") -> 105.51471
A38: =IFERROR(INDEX('Comparativo de Marcas'!$A:$A,MATCH(36,'Comparativo de Marcas'!$M:$M,0)),"") -> MAVALA | B38: =IFERROR(INDEX('Comparativo de Marcas'!$B:$B,MATCH(36,'Comparativo de Marcas'!$M:$M,0)),"") -> Outros/Diversos | C38: =IFERROR(INDEX('Comparativo de Marcas'!$C:$C,MATCH(36,'Comparativo de Marcas'!$M:$M,0)),"") -> 74560 | D38: =IFERROR(INDEX('Comparativo de Marcas'!$D:$D,MATCH(36,'Comparativo de Marcas'!$M:$M,0)),"") -> 0 | E38: =IFERROR(INDEX('Comparativo de Marcas'!$E:$E,MATCH(36,'Comparativo de Marcas'!$M:$M,0)),"") -> 0 | F38: =IFERROR(INDEX('Comparativo de Marcas'!$F:$F,MATCH(36,'Comparativo de Marcas'!$M:$M,0)),"") -> 74560 | G38: =IFERROR(INDEX('Comparativo de Marcas'!$G:$G,MATCH(36,'Comparativo de Marcas'!$M:$M,0)),"") -> 662 | H38: =IFERROR(INDEX('Comparativo de Marcas'!$I:$I,MATCH(36,'Comparativo de Marcas'!$M:$M,0)),"") -> 112.6284
A39: =IFERROR(INDEX('Comparativo de Marcas'!$A:$A,MATCH(37,'Comparativo de Marcas'!$M:$M,0)),"") -> MONTBLANC | B39: =IFERROR(INDEX('Comparativo de Marcas'!$B:$B,MATCH(37,'Comparativo de Marcas'!$M:$M,0)),"") -> Perfumaria/Colonia | C39: =IFERROR(INDEX('Comparativo de Marcas'!$C:$C,MATCH(37,'Comparativo de Marcas'!$M:$M,0)),"") -> 3000 | D39: =IFERROR(INDEX('Comparativo de Marcas'!$D:$D,MATCH(37,'Comparativo de Marcas'!$M:$M,0)),"") -> 45370 | E39: =IFERROR(INDEX('Comparativo de Marcas'!$E:$E,MATCH(37,'Comparativo de Marcas'!$M:$M,0)),"") -> 24380 | F39: =IFERROR(INDEX('Comparativo de Marcas'!$F:$F,MATCH(37,'Comparativo de Marcas'!$M:$M,0)),"") -> 72750 | G39: =IFERROR(INDEX('Comparativo de Marcas'!$G:$G,MATCH(37,'Comparativo de Marcas'!$M:$M,0)),"") -> 131 | H39: =IFERROR(INDEX('Comparativo de Marcas'!$I:$I,MATCH(37,'Comparativo de Marcas'!$M:$M,0)),"") -> 555.34351
A40: =IFERROR(INDEX('Comparativo de Marcas'!$A:$A,MATCH(38,'Comparativo de Marcas'!$M:$M,0)),"") -> BLACK & DECKER | B40: =IFERROR(INDEX('Comparativo de Marcas'!$B:$B,MATCH(38,'Comparativo de Marcas'!$M:$M,0)),"") -> Ferramentas | C40: =IFERROR(INDEX('Comparativo de Marcas'!$C:$C,MATCH(38,'Comparativo de Marcas'!$M:$M,0)),"") -> 71620 | D40: =IFERROR(INDEX('Comparativo de Marcas'!$D:$D,MATCH(38,'Comparativo de Marcas'!$M:$M,0)),"") -> 0 | E40: =IFERROR(INDEX('Comparativo de Marcas'!$E:$E,MATCH(38,'Comparativo de Marcas'!$M:$M,0)),"") -> 0 | F40: =IFERROR(INDEX('Comparativo de Marcas'!$F:$F,MATCH(38,'Comparativo de Marcas'!$M:$M,0)),"") -> 71620 | G40: =IFERROR(INDEX('Comparativo de Marcas'!$G:$G,MATCH(38,'Comparativo de Marcas'!$M:$M,0)),"") -> 563 | H40: =IFERROR(INDEX('Comparativo de Marcas'!$I:$I,MATCH(38,'Comparativo de Marcas'!$M:$M,0)),"") -> 127.21137
...

Sheet Comparativo de Marcas
A1: Marca | B1: Categoria (predominante) | C1: Receita SIENO (R$) | D1: Receita BAGATELLE (R$) | E1: Receita AUMA (R$) | F1: Receita Total (R$) | G1: Unidades Total | H1: Nº Anúncios Total | I1: Ticket Médio (R$) | J1: Nº Concorrentes que vendem | K1: Vendida pelos 3? | L1: Oportunidade (ticket>=R$100 e >=100 unid.) | M1: Rank Oportunidade (auxiliar)
A2: CAROLINA HERRERA | B2: Perfumaria/Colonia | C2: =SUMIFS('Dados Brutos'!$C:$C,'Dados Brutos'!$B:$B,A2,'Dados Brutos'!$T:$T,"SIENO") -> 0 | D2: =SUMIFS('Dados Brutos'!$C:$C,'Dados Brutos'!$B:$B,A2,'Dados Brutos'!$T:$T,"BAGATELLE") -> 1332020 | E2: =SUMIFS('Dados Brutos'!$C:$C,'Dados Brutos'!$B:$B,A2,'Dados Brutos'!$T:$T,"AUMA") -> 2191200 | F2: =SUM(C2:E2) -> 3523220 | G2: =SUMIF('Dados Brutos'!$B:$B,A2,'Dados Brutos'!$D:$D) -> 5687 | H2: =COUNTIF('Dados Brutos'!$B:$B,A2) -> 354 | I2: =IFERROR(F2/G2,0) -> 619.52172 | J2: =(C2>0)+(D2>0)+(E2>0) -> 2 | K2: =IF(J2=3,"Sim","Não") -> Não | L2: =IF(AND(I2>=100,G2>=100),"Sim","Não") -> Sim | M2: =IF(L2="Sim",SUMPRODUCT(($L$2:L2="Sim")*1),"") -> 1
A3: RABANNE | B3: Perfumaria/Colonia | C3: =SUMIFS('Dados Brutos'!$C:$C,'Dados Brutos'!$B:$B,A3,'Dados Brutos'!$T:$T,"SIENO") -> 0 | D3: =SUMIFS('Dados Brutos'!$C:$C,'Dados Brutos'!$B:$B,A3,'Dados Brutos'!$T:$T,"BAGATELLE") -> 921250 | E3: =SUMIFS('Dados Brutos'!$C:$C,'Dados Brutos'!$B:$B,A3,'Dados Brutos'!$T:$T,"AUMA") -> 1517680 | F3: =SUM(C3:E3) -> 2438930 | G3: =SUMIF('Dados Brutos'!$B:$B,A3,'Dados Brutos'!$D:$D) -> 3685 | H3: =COUNTIF('Dados Brutos'!$B:$B,A3) -> 320 | I3: =IFERROR(F3/G3,0) -> 661.85346 | J3: =(C3>0)+(D3>0)+(E3>0) -> 2 | K3: =IF(J3=3,"Sim","Não") -> Não | L3: =IF(AND(I3>=100,G3>=100),"Sim","Não") -> Sim | M3: =IF(L3="Sim",SUMPRODUCT(($L$2:L3="Sim")*1),"") -> 2
A4: JEAN PAUL GAULTIER | B4: Perfumaria/Colonia | C4: =SUMIFS('Dados Brutos'!$C:$C,'Dados Brutos'!$B:$B,A4,'Dados Brutos'!$T:$T,"SIENO") -> 0 | D4: =SUMIFS('Dados Brutos'!$C:$C,'Dados Brutos'!$B:$B,A4,'Dados Brutos'!$T:$T,"BAGATELLE") -> 387830 | E4: =SUMIFS('Dados Brutos'!$C:$C,'Dados Brutos'!$B:$B,A4,'Dados Brutos'!$T:$T,"AUMA") -> 1397570 | F4: =SUM(C4:E4) -> 1785400 | G4: =SUMIF('Dados Brutos'!$B:$B,A4,'Dados Brutos'!$D:$D) -> 2595 | H4: =COUNTIF('Dados Brutos'!$B:$B,A4) -> 255 | I4: =IFERROR(F4/G4,0) -> 688.01541 | J4: =(C4>0)+(D4>0)+(E4>0) -> 2 | K4: =IF(J4=3,"Sim","Não") -> Não | L4: =IF(AND(I4>=100,G4>=100),"Sim","Não") -> Sim | M4: =IF(L4="Sim",SUMPRODUCT(($L$2:L4="Sim")*1),"") -> 3
A5: G-TECH | B5: Saude/Bem-estar | C5: =SUMIFS('Dados Brutos'!$C:$C,'Dados Brutos'!$B:$B,A5,'Dados Brutos'!$T:$T,"SIENO") -> 1429210 | D5: =SUMIFS('Dados Brutos'!$C:$C,'Dados Brutos'!$B:$B,A5,'Dados Brutos'!$T:$T,"BAGATELLE") -> 0 | E5: =SUMIFS('Dados Brutos'!$C:$C,'Dados Brutos'!$B:$B,A5,'Dados Brutos'!$T:$T,"AUMA") -> 0 | F5: =SUM(C5:E5) -> 1429210 | G5: =SUMIF('Dados Brutos'!$B:$B,A5,'Dados Brutos'!$D:$D) -> 16001 | H5: =COUNTIF('Dados Brutos'!$B:$B,A5) -> 25 | I5: =IFERROR(F5/G5,0) -> 89.320042 | J5: =(C5>0)+(D5>0)+(E5>0) -> 1 | K5: =IF(J5=3,"Sim","Não") -> Não | L5: =IF(AND(I5>=100,G5>=100),"Sim","Não") -> Não | M5: =IF(L5="Sim",SUMPRODUCT(($L$2:L5="Sim")*1),"")
A6: YVES SAINT LAURENT | B6: Perfumaria/Colonia | C6: =SUMIFS('Dados Brutos'!$C:$C,'Dados Brutos'!$B:$B,A6,'Dados Brutos'!$T:$T,"SIENO") -> 253760 | D6: =SUMIFS('Dados Brutos'!$C:$C,'Dados Brutos'!$B:$B,A6,'Dados Brutos'!$T:$T,"BAGATELLE") -> 17620 | E6: =SUMIFS('Dados Brutos'!$C:$C,'Dados Brutos'!$B:$B,A6,'Dados Brutos'!$T:$T,"AUMA") -> 521750 | F6: =SUM(C6:E6) -> 793130 | G6: =SUMIF('Dados Brutos'!$B:$B,A6,'Dados Brutos'!$D:$D) -> 1123 | H6: =COUNTIF('Dados Brutos'!$B:$B,A6) -> 75 | I6: =IFERROR(F6/G6,0) -> 706.26002 | J6: =(C6>0)+(D6>0)+(E6>0) -> 3 | K6: =IF(J6=3,"Sim","Não") -> Sim | L6: =IF(AND(I6>=100,G6>=100),"Sim","Não") -> Sim | M6: =IF(L6="Sim",SUMPRODUCT(($L$2:L6="Sim")*1),"") -> 4
A7: DOLCE & GABBANA | B7: Perfumaria/Colonia | C7: =SUMIFS('Dados Brutos'!$C:$C,'Dados Brutos'!$B:$B,A7,'Dados Brutos'!$T:$T,"SIENO") -> 178890 | D7: =SUMIFS('Dados Brutos'!$C:$C,'Dados Brutos'!$B:$B,A7,'Dados Brutos'!$T:$T,"BAGATELLE") -> 99900 | E7: =SUMIFS('Dados Brutos'!$C:$C,'Dados Brutos'!$B:$B,A7,'Dados Brutos'!$T:$T,"AUMA") -> 170460 | F7: =SUM(C7:E7) -> 449250 | G7: =SUMIF('Dados Brutos'!$B:$B,A7,'Dados Brutos'!$D:$D) -> 670 | H7: =COUNTIF('Dados Brutos'!$B:$B,A7) -> 112 | I7: =IFERROR(F7/G7,0) -> 670.52239 | J7: =(C7>0)+(D7>0)+(E7>0) -> 3 | K7: =IF(J7=3,"Sim","Não") -> Sim | L7: =IF(AND(I7>=100,G7>=100),"Sim","Não") -> Sim | M7: =IF(L7="Sim",SUMPRODUCT(($L$2:L7="Sim")*1),"") -> 5
A8: SHISEIDO | B8: Perfumaria/Colonia | C8: =SUMIFS('Dados Brutos'!$C:$C,'Dados Brutos'!$B:$B,A8,'Dados Brutos'!$T:$T,"SIENO") -> 0 | D8: =SUMIFS('Dados Brutos'!$C:$C,'Dados Brutos'!$B:$B,A8,'Dados Brutos'!$T:$T,"BAGATELLE") -> 0 | E8: =SUMIFS('Dados Brutos'!$C:$C,'Dados Brutos'!$B:$B,A8,'Dados Brutos'!$T:$T,"AUMA") -> 447230 | F8: =SUM(C8:E8) -> 447230 | G8: =SUMIF('Dados Brutos'!$B:$B,A8,'Dados Brutos'!$D:$D) -> 1310 | H8: =COUNTIF('Dados Brutos'!$B:$B,A8) -> 108 | I8: =IFERROR(F8/G8,0) -> 341.39695 | J8: =(C8>0)+(D8>0)+(E8>0) -> 1 | K8: =IF(J8=3,"Sim","Não") -> Não | L8: =IF(AND(I8>=100,G8>=100),"Sim","Não") -> Sim | M8: =IF(L8="Sim",SUMPRODUCT(($L$2:L8="Sim")*1),"") -> 6
A9: LANCÔME | B9: Perfumaria/Colonia | C9: =SUMIFS('Dados Brutos'!$C:$C,'Dados Brutos'!$B:$B,A9,'Dados Brutos'!$T:$T,"SIENO") -> 0 | D9: =SUMIFS('Dados Brutos'!$C:$C,'Dados Brutos'!$B:$B,A9,'Dados Brutos'!$T:$T,"BAGATELLE") -> 0 | E9: =SUMIFS('Dados Brutos'!$C:$C,'Dados Brutos'!$B:$B,A9,'Dados Brutos'!$T:$T,"AUMA") -> 443410 | F9: =SUM(C9:E9) -> 443410 | G9: =SUMIF('Dados Brutos'!$B:$B,A9,'Dados Brutos'!$D:$D) -> 774 | H9: =COUNTIF('Dados Brutos'!$B:$B,A9) -> 124 | I9: =IFERROR(F9/G9,0) -> 572.88114 | J9: =(C9>0)+(D9>0)+(E9>0) -> 1 | K9: =IF(J9=3,"Sim","Não") -> Não | L9: =IF(AND(I9>=100,G9>=100),"Sim","Não") -> Sim | M9: =IF(L9="Sim",SUMPRODUCT(($L$2:L9="Sim")*1),"") -> 7
A10: PRADA | B10: Perfumaria/Colonia | C10: =SUMIFS('Dados Brutos'!$C:$C,'Dados Brutos'!$B:$B,A10,'Dados Brutos'!$T:$T,"SIENO") -> 33000 | D10: =SUMIFS('Dados Brutos'!$C:$C,'Dados Brutos'!$B:$B,A10,'Dados Brutos'!$T:$T,"BAGATELLE") -> 940 | E10: =SUMIFS('Dados Brutos'!$C:$C,'Dados Brutos'!$B:$B,A10,'Dados Brutos'!$T:$T,"AUMA") -> 372630 | F10: =SUM(C10:E10) -> 406570 | G10: =SUMIF('Dados Brutos'!$B:$B,A10,'Dados Brutos'!$D:$D) -> 519 | H10: =COUNTIF('Dados Brutos'!$B:$B,A10) -> 44 | I10: =IFERROR(F10/G10,0) -> 783.37187 | J10: =(C10>0)+(D10>0)+(E10>0) -> 3 | K10: =IF(J10=3,"Sim","Não") -> Sim | L10: =IF(AND(I10>=100,G10>=100),"Sim","Não") -> Sim | M10: =IF(L10="Sim",SUMPRODUCT(($L$2:L10="Sim")*1),"") -> 8
A11: ARMANI BEAUTY | B11: Perfumaria/Colonia | C11: =SUMIFS('Dados Brutos'!$C:$C,'Dados Brutos'!$B:$B,A11,'Dados Brutos'!$T:$T,"SIENO") -> 0 | D11: =SUMIFS('Dados Brutos'!$C:$C,'Dados Brutos'!$B:$B,A11,'Dados Brutos'!$T:$T,"BAGATELLE") -> 0 | E11: =SUMIFS('Dados Brutos'!$C:$C,'Dados Brutos'!$B:$B,A11,'Dados Brutos'!$T:$T,"AUMA") -> 402220 | F11: =SUM(C11:E11) -> 402220 | G11: =SUMIF('Dados Brutos'!$B:$B,A11,'Dados Brutos'!$D:$D) -> 540 | H11: =COUNTIF('Dados Brutos'!$B:$B,A11) -> 83 | I11: =IFERROR(F11/G11,0) -> 744.85185 | J11: =(C11>0)+(D11>0)+(E11>0) -> 1 | K11: =IF(J11=3,"Sim","Não") -> Não | L11: =IF(AND(I11>=100,G11>=100),"Sim","Não") -> Sim | M11: =IF(L11="Sim",SUMPRODUCT(($L$2:L11="Sim")*1),"") -> 9
A12: VITAFOR | B12: Suplementos/Nutricao | C12: =SUMIFS('Dados Brutos'!$C:$C,'Dados Brutos'!$B:$B,A12,'Dados Brutos'!$T:$T,"SIENO") -> 358960 | D12: =SUMIFS('Dados Brutos'!$C:$C,'Dados Brutos'!$B:$B,A12,'Dados Brutos'!$T:$T,"BAGATELLE") -> 0 | E12: =SUMIFS('Dados Brutos'!$C:$C,'Dados Brutos'!$B:$B,A12,'Dados Brutos'!$T:$T,"AUMA") -> 0 | F12: =SUM(C12:E12) -> 358960 | G12: =SUMIF('Dados Brutos'!$B:$B,A12,'Dados Brutos'!$D:$D) -> 4666 | H12: =COUNTIF('Dados Brutos'!$B:$B,A12) -> 40 | I12: =IFERROR(F12/G12,0) -> 76.93099 | J12: =(C12>0)+(D12>0)+(E12>0) -> 1 | K12: =IF(J12=3,"Sim","Não") -> Não | L12: =IF(AND(I12>=100,G12>=100),"Sim","Não") -> Não | M12: =IF(L12="Sim",SUMPRODUCT(($L$2:L12="Sim")*1),"")
A13: MARURI | B13: Pesca/Nautica | C13: =SUMIFS('Dados Brutos'!$C:$C,'Dados Brutos'!$B:$B,A13,'Dados Brutos'!$T:$T,"SIENO") -> 344600 | D13: =SUMIFS('Dados Brutos'!$C:$C,'Dados Brutos'!$B:$B,A13,'Dados Brutos'!$T:$T,"BAGATELLE") -> 0 | E13: =SUMIFS('Dados Brutos'!$C:$C,'Dados Brutos'!$B:$B,A13,'Dados Brutos'!$T:$T,"AUMA") -> 0 | F13: =SUM(C13:E13) -> 344600 | G13: =SUMIF('Dados Brutos'!$B:$B,A13,'Dados Brutos'!$D:$D) -> 1042 | H13: =COUNTIF('Dados Brutos'!$B:$B,A13) -> 16 | I13: =IFERROR(F13/G13,0) -> 330.71017 | J13: =(C13>0)+(D13>0)+(E13>0) -> 1 | K13: =IF(J13=3,"Sim","Não") -> Não | L13: =IF(AND(I13>=100,G13>=100),"Sim","Não") -> Sim | M13: =IF(L13="Sim",SUMPRODUCT(($L$2:L13="Sim")*1),"") -> 10
... A276: A BOTICA BRASIL | B276: Cosmeticos/Skincare | C276: =SUMIFS('Dados Brutos'!$C:$C,'Dados Brutos'!$B:$B,A276,'Dados Brutos'!$T:$T,"SIENO") -> 40 | D276: =SUMIFS('Dados Brutos'!$C:$C,'Dados Brutos'!$B:$B,A276,'Dados Brutos'!$T:$T,"BAGATELLE") -> 0 | E276: =SUMIFS('Dados Brutos'!$C:$C,'Dados Brutos'!$B:$B,A276,'Dados Brutos'!$T:$T,"AUMA") -> 0 | F276: =SUM(C276:E276) -> 40 | G276: =SUMIF('Dados Brutos'!$B:$B,A276,'Dados Brutos'!$D:$D) -> 1 | H276: =COUNTIF('Dados Brutos'!$B:$B,A276) -> 1 | I276: =IFERROR(F276/G276,0) -> 40 | J276: =(C276>0)+(D276>0)+(E276>0) -> 1 | K276: =IF(J276=3,"Sim","Não") -> Não | L276: =IF(AND(I276>=100,G276>=100),"Sim","Não") -> Não | M276: =IF(L276="Sim",SUMPRODUCT(($L$2:L276="Sim")*1),"")
A277: TOTAL | C277: =SUM(C2:C276) -> 8228730 | D277: =SUM(D2:D276) -> 3808650 | E277: =SUM(E2:E276) -> 9294080 | F277: =SUM(F2:F276) -> 21331460 | G277: =SUM(G2:G276) -> 104250 | H277: =SUM(H2:H276) -> 3988 | I277: =IFERROR(F277/G277,0) -> 204.61832

Sheet Por Categoria
A1: Categoria | B1: Nº de Marcas | C1: Receita (R$) | D1: Unidades Vendidas | E1: Nº Anúncios (SKUs) | F1: Ticket Médio (R$) | G1: % da Receita Total
A2: Perfumaria/Colonia | B2: =SUMIFS('Dados Brutos'!$V:$V,'Dados Brutos'!$U:$U,A2) -> 125 | C2: =SUMIF('Dados Brutos'!$U:$U,A2,'Dados Brutos'!$C:$C) -> 15170130 | D2: =SUMIF('Dados Brutos'!$U:$U,A2,'Dados Brutos'!$D:$D) -> 43229 | E2: =COUNTIF('Dados Brutos'!$U:$U,A2) -> 3058 | F2: =IFERROR(C2/D2,0) -> 350.92484 | G2: =IFERROR(C2/$C$15,0) -> 0.71116229
A3: Saude/Bem-estar | B3: =SUMIFS('Dados Brutos'!$V:$V,'Dados Brutos'!$U:$U,A3) -> 13 | C3: =SUMIF('Dados Brutos'!$U:$U,A3,'Dados Brutos'!$C:$C) -> 1946030 | D3: =SUMIF('Dados Brutos'!$U:$U,A3,'Dados Brutos'!$D:$D) -> 23460 | E3: =COUNTIF('Dados Brutos'!$U:$U,A3) -> 45 | F3: =IFERROR(C3/D3,0) -> 82.95098 | G3: =IFERROR(C3/$C$15,0) -> 0.091228167
A4: Outros/Diversos | B4: =SUMIFS('Dados Brutos'!$V:$V,'Dados Brutos'!$U:$U,A4) -> 75 | C4: =SUMIF('Dados Brutos'!$U:$U,A4,'Dados Brutos'!$C:$C) -> 936200 | D4: =SUMIF('Dados Brutos'!$U:$U,A4,'Dados Brutos'!$D:$D) -> 10368 | E4: =COUNTIF('Dados Brutos'!$U:$U,A4) -> 464 | F4: =IFERROR(C4/D4,0) -> 90.297068 | G4: =IFERROR(C4/$C$15,0) -> 0.043888229
A5: Pesca/Nautica | B5: =SUMIFS('Dados Brutos'!$V:$V,'Dados Brutos'!$U:$U,A5) -> 5 | C5: =SUMIF('Dados Brutos'!$U:$U,A5,'Dados Brutos'!$C:$C) -> 846880 | D5: =SUMIF('Dados Brutos'!$U:$U,A5,'Dados Brutos'!$D:$D) -> 2987 | E5: =COUNTIF('Dados Brutos'!$U:$U,A5) -> 44 | F5: =IFERROR(C5/D5,0) -> 283.52193 | G5: =IFERROR(C5/$C$15,0) -> 0.039700986
A6: Suplementos/Nutricao | B6: =SUMIFS('Dados Brutos'!$V:$V,'Dados Brutos'!$U:$U,A6) -> 10 | C6: =SUMIF('Dados Brutos'!$U:$U,A6,'Dados Brutos'!$C:$C) -> 723280 | D6: =SUMIF('Dados Brutos'!$U:$U,A6,'Dados Brutos'!$D:$D) -> 10505 | E6: =COUNTIF('Dados Brutos'!$U:$U,A6) -> 71 | F6: =IFERROR(C6/D6,0) -> 68.851023 | G6: =IFERROR(C6/$C$15,0) -> 0.033906727
A7: Cosmeticos/Skincare | B7: =SUMIFS('Dados Brutos'!$V:$V,'Dados Brutos'!$U:$U,A7) -> 21 | C7: =SUMIF('Dados Brutos'!$U:$U,A7,'Dados Brutos'!$C:$C) -> 501660 | D7: =SUMIF('Dados Brutos'!$U:$U,A7,'Dados Brutos'!$D:$D) -> 4723 | E7: =COUNTIF('Dados Brutos'!$U:$U,A7) -> 181 | F7: =IFERROR(C7/D7,0) -> 106.21639 | G7: =IFERROR(C7/$C$15,0) -> 0.023517378
A8: Ferramentas | B8: =SUMIFS('Dados Brutos'!$V:$V,'Dados Brutos'!$U:$U,A8) -> 8 | C8: =SUMIF('Dados Brutos'!$U:$U,A8,'Dados Brutos'!$C:$C) -> 396480 | D8: =SUMIF('Dados Brutos'!$U:$U,A8,'Dados Brutos'!$D:$D) -> 1926 | E8: =COUNTIF('Dados Brutos'!$U:$U,A8) -> 31 | F8: =IFERROR(C8/D8,0) -> 205.8567 | G8: =IFERROR(C8/$C$15,0) -> 0.018586632
A9: Casa/Eletrodomesticos | B9: =SUMIFS('Dados Brutos'!$V:$V,'Dados Brutos'!$U:$U,A9) -> 6 | C9: =SUMIF('Dados Brutos'!$U:$U,A9,'Dados Brutos'!$C:$C) -> 231670 | D9: =SUMIF('Dados Brutos'!$U:$U,A9,'Dados Brutos'!$D:$D) -> 1566 | E9: =COUNTIF('Dados Brutos'!$U:$U,A9) -> 23 | F9: =IFERROR(C9/D9,0) -> 147.93742 | G9: =IFERROR(C9/$C$15,0) -> 0.010860485
A10: Eletronicos/Games | B10: =SUMIFS('Dados Brutos'!$V:$V,'Dados Brutos'!$U:$U,A10) -> 6 | C10: =SUMIF('Dados Brutos'!$U:$U,A10,'Dados Brutos'!$C:$C) -> 159630 | D10: =SUMIF('Dados Brutos'!$U:$U,A10,'Dados Brutos'!$D:$D) -> 1666 | E10: =COUNTIF('Dados Brutos'!$U:$U,A10) -> 17 | F10: =IFERROR(C10/D10,0) -> 95.816327 | G10: =IFERROR(C10/$C$15,0) -> 0.0074833134
A11: Utensilios Cozinha/Jardim | B11: =SUMIFS('Dados Brutos'!$V:$V,'Dados Brutos'!$U:$U,A11) -> 2 | C11: =SUMIF('Dados Brutos'!$U:$U,A11,'Dados Brutos'!$C:$C) -> 155300 | D11: =SUMIF('Dados Brutos'!$U:$U,A11,'Dados Brutos'!$D:$D) -> 1790 | E11: =COUNTIF('Dados Brutos'!$U:$U,A11) -> 5 | F11: =IFERROR(C11/D11,0) -> 86.759777 | G11: =IFERROR(C11/$C$15,0) -> 0.0072803268
A12: Tatico/Outdoor | B12: =SUMIFS('Dados Brutos'!$V:$V,'Dados Brutos'!$U:$U,A12) -> 1 | C12: =SUMIF('Dados Brutos'!$U:$U,A12,'Dados Brutos'!$C:$C) -> 154520 | D12: =SUMIF('Dados Brutos'!$U:$U,A12,'Dados Brutos'!$D:$D) -> 1033 | E12: =COUNTIF('Dados Brutos'!$U:$U,A12) -> 38 | F12: =IFERROR(C12/D12,0) -> 149.58374 | G12: =IFERROR(C12/$C$15,0) -> 0.0072437611
A13: Automotivo | B13: =SUMIFS('Dados Brutos'!$V:$V,'Dados Brutos'!$U:$U,A13) -> 1 | C13: =SUMIF('Dados Brutos'!$U:$U,A13,'Dados Brutos'!$C:$C) -> 77840 | D13: =SUMIF('Dados Brutos'!$U:$U,A13,'Dados Brutos'!$D:$D) -> 766 | E13: =COUNTIF('Dados Brutos'!$U:$U,A13) -> 8 | F13: =IFERROR(C13/D13,0) -> 101.6188 | G13: =IFERROR(C13/$C$15,0) -> 0.0036490704
A14: Bike/Ciclismo | B14: =SUMIFS('Dados Brutos'!$V:$V,'Dados Brutos'!$U:$U,A14) -> 2 | C14: =SUMIF('Dados Brutos'!$U:$U,A14,'Dados Brutos'!$C:$C) -> 31840 | D14: =SUMIF('Dados Brutos'!$U:$U,A14,'Dados Brutos'!$D:$D) -> 231 | E14: =COUNTIF('Dados Brutos'!$U:$U,A14) -> 3 | F14: =IFERROR(C14/D14,0) -> 137.8355 | G14: =IFERROR(C14/$C$15,0) -> 0.0014926311
A15: TOTAL | B15: =SUM(B2:B14) -> 275 | C15: =SUM(C2:C14) -> 21331460 | D15: =SUM(D2:D14) -> 104250 | E15: =SUM(E2:E14) -> 3988 | F15: =IFERROR(C15/D15,0) -> 204.61832 | G15: =SUM(G2:G14) -> 1

Sheet Produtos por GTIN
A1: Produtos consolidados por GTIN (código de barras) — 2142 produtos únicos, a partir de 3988 anúncios (351 sem GTIN válido no cadastro, não entraram aqui)
A2: 310 desses GTINs aparecem em mais de um concorrente — o mesmo produto físico, permitindo comparar o preço de cada um lado a lado. Tabela fixa gerada nesta versão do relatório (não recalcula sozinha se os Dados Brutos forem editados).
A4: GTIN | B4: Marca | C4: Categoria | D4: Tamanho (detectado) | E4: Título representativo | F4: Nº Concorrentes | G4: Nº Anúncios consolidados | H4: Receita Total (R$) | I4: Unidades Total | J4: Preço Médio Ponderado (R$) | K4: Preço Médio SIENO (R$) | L4: Preço Médio BAGATELLE (R$) | M4: Preço Médio AUMA (R$) | N4: Diferença de Preço entre Concorrentes (%)
A5: 8411061838778 | B5: CAROLINA HERRERA | C5: Perfumaria/Colonia | D5: 125ml | E5: Perfume 212 Vip Rosé Carolina Herrera Ea | F5: 2 | G5: 8 | H5: 522480 | I5: 811 | J5: 644.24168 | L5: 633.96825 | M5: 656.48649 | N5: 0.035519495
A6: 7898639690388 | B6: G-TECH | C6: Saude/Bem-estar | D6: Não identificado no título | E6: Aparelho De Medir Pressão Digital De Bra | F6: 1 | G6: 2 | H6: 409000 | I6: 3800 | J6: 107.63158 | K6: 107.63158
A7: 3349668566372 | B7: RABANNE | C7: Perfumaria/Colonia | D7: 200ml | E7: Perfume Rabanne 1 Million Eau De Toilett | F7: 2 | G7: 8 | H7: 364890 | I7: 565 | J7: 645.82301 | L7: 624.91909 | M7: 671.05469 | N7: 0.073826507
A8: 8435415032360 | B8: JEAN PAUL GAULTIER | C8: Perfumaria/Colonia | D8: Não identificado no título | E8: Perfume Jean Paul Gaultier Le Male Le Pa | F8: 2 | G8: 6 | H8: 327100 | I8: 457 | J8: 715.75492 | L8: 842.30769 | M8: 699.50617 | N8: 0.20414619
A9: 8435415076906 | B9: JEAN PAUL GAULTIER | C9: Perfumaria/Colonia | D9: 200ml | E9: Perfume Jean Paul Gaultier Le Male Elixi | F9: 2 | G9: 6 | H9: 313400 | I9: 471 | J9: 665.39278 | L9: 1071.4286 | M9: 659.26724 | N9: 0.62518096
A10: 7898301059895 | B10: G-TECH | C10: Saude/Bem-estar | D10: Não identificado no título | E10: Oxímetro De Dedo Digital Portátil Pulso | F10: 1 | G10: 2 | H10: 293000 | I10: 3100 | J10: 94.516129 | K10: 94.516129
A11: 8411061120620 | B11: CAROLINA HERRERA | C11: Perfumaria/Colonia | D11: Não identificado no título | E11: Perfume Carolina Herrera 212 Vip Black E | F11: 1 | G11: 3 | H11: 282990 | I11: 483 | J11: 585.90062 | L11: 585.90062
A12: 3349668592388 | B12: RABANNE | C12: Perfumaria/Colonia | D12: Não identificado no título | E12: Perfume Rabanne Invictus Victory Eau De | F12: 2 | G12: 7 | H12: 222200 | I12: 324 | J12: 685.80247 | L12: 797.10145 | M12: 655.68627 | N12: 0.21567506
A13: 3349668589678 | B13: RABANNE | C13: Perfumaria/Colonia | D13: 200ml | E13: Perfume Rabanne Invictus Eau De Toilette | F13: 2 | G13: 3 | H13: 202100 | I13: 302 | J13: 669.2053 | L13: 700 | M13: 669 | N13: 0.046337818
A14: 7898639692924 | B14: G-TECH | C14: Saude/Bem-estar | D14: Não identificado no título | E14: Aparelho Medidor De Pressão Arterial Dig | F14: 1 | G14: 2 | H14: 185800 | I14: 1410 | J14: 131.77305 | K14: 131.77305
A15: 3614273760164 | B15: PRADA | C15: Perfumaria/Colonia | D15: 90ml | E15: Perfume Feminino Prada Paradoxe Eau De | F15: 2 | G15: 6 | H15: 174200 | I15: 227 | J15: 767.40088 | K15: 660 | M15: 797.74011 | N15: 0.20869714
A16: 3349666007921 | B16: RABANNE | C16: Perfumaria/Colonia | D16: 100ml | E16: Perfume Rabanne 1 Million Eau De Toilett | F16: 2 | G16: 7 | H16: 167280 | I16: 346 | J16: 483.46821 | L16: 481.56028 | M16: 491.875 | N16: 0.021419367
A17: 8411061023655 | B17: CAROLINA HERRERA | C17: Perfumaria/Colonia | D17: Não identificado no título | E17: Perfume Carolina Herrera 212 Men Heroes | F17: 1 | G17: 2 | H17: 151200 | I17: 262 | J17: 577.09924 | M17: 577.09924
A18: 729238146587 | B18: SHISEIDO | C18: Perfumaria/Colonia | D18: Não identificado no título | E18: Shiseido Bb For Sports Fps 50 Medium Bas | F18: 1 | G18: 2 | H18: 147500 | I18: 485 | J18: 304.12371 | M18: 304.12371
A19: 3349668614530 | B19: RABANNE | C19: Perfumaria/Colonia | D19: Não identificado no título | E19: Perfume Rabanne Invictus Victory Elixir | F19: 2 | G19: 9 | H19: 147070 | I19: 208 | J19: 707.06731 | L19: 781.66667 | M19: 684.6875 | N19: 0.14164004
A20: 8411061853207 | B20: CAROLINA HERRERA | C20: Perfumaria/Colonia | D20: 200ml | E20: Perfume Carolina Herrera 212 Men Nyc Eau | F20: 2 | G20: 5 | H20: 138040 | I20: 206 | J20: 670.09709 | L20: 651.84211 | M20: 680.76923 | N20: 0.044377504
A21: 7908407005693 | B21: RITUÁRIA | C21: Suplementos/Nutricao | D21: Não identificado no título | E21: Suplemento Fibras Alimentares Prebiótica | F21: 1 | G21: 2 | H21: 137900 | I21: 2300 | J21: 59.956522 | K21: 59.956522
A22: 3349668581948 | B22: RABANNE | C22: Perfumaria/Colonia | D22: 200ml | E22: Perfume Rabanne 1 Million Parfum 200 Ml | F22: 2 | G22: 9 | H22: 137680 | I22: 173 | J22: 795.83815 | L22: 940 | M22: 794.15205 | N22: 0.18365243
A23: 8435415076937 | B23: JEAN PAUL GAULTIER | C23: Perfumaria/Colonia | D23: Não identificado no título | E23: Perfume Jean Paul Gaultier Le Male Elixi | F23: 2 | G23: 7 | H23: 137180 | I23: 288 | J23: 476.31944 | L23: 646.66667 | M23: 474.52632 | N23: 0.3627625
A24: 3614273069557 | B24: YVES SAINT LAURENT | C24: Perfumaria/Colonia | D24: Não identificado no título | E24: Yves Saint Laurent Libre Intense Feminin | F24: 1 | G24: 4 | H24: 123100 | I24: 144 | J24: 854.86111 | M24: 854.86111
A25: 7898301054494 | B25: PREMIUM | C25: Saude/Bem-estar | D25: Não identificado no título | E25: Aparelho De Pressão Arterial Manual Esfi | F25: 1 | G25: 2 | H25: 122270 | I25: 1802 | J25: 67.852386 | K25: 67.852386
A26: 7898639690999 | B26: G-TECH | C26: Saude/Bem-estar | D26: Não identificado no título | E26: Oxímetro Led G-tech Branco/azul | F26: 1 | G26: 1 | H26: 121000 | I26: 1700 | J26: 71.176471 | K26: 71.176471
A27: 3605533286555 | B27: LANCÔME | C27: Perfumaria/Colonia | D27: Não identificado no título | E27: Perfume Feminino L' Eau De Parfum Fragrâ | F27: 1 | G27: 5 | H27: 118880 | I27: 170 | J27: 699.29412 | M27: 699.29412
A28: 729238146570 | B28: SHISEIDO | C28: Perfumaria/Colonia | D28: Não identificado no título | E28: Shiseido Bb For Sports Fps 50 Light - Ba | F28: 1 | G28: 5 | H28: 115890 | I28: 372 | J28: 311.53226 | M28: 311.53226
A29: 7899952324523 | B29: JEQUITI | C29: Perfumaria/Colonia | D29: Não identificado no título | E29: Perfumes Colônia Miniatura Cebolinha Tur | F29: 1 | G29: 2 | H29: 110500 | I29: 4960 | J29: 22.278226 | K29: 22.278226
A30: 3614273852814 | B30: YVES SAINT LAURENT | C30: Perfumaria/Colonia | D30: Não identificado no título | E30: Yves Saint Laurent Myslf Edp - Perfume M | F30: 2 | G30: 3 | H30: 108800 | I30: 152 | J30: 715.78947 | K30: 707.69231 | M30: 763.63636 | N30: 0.079051383
A31: 3349668627547 | B31: RABANNE | C31: Perfumaria/Colonia | D31: 200ml | E31: Perfume Rabanne Invictus Parfum 200ml Ma | F31: 2 | G31: 4 | H31: 103660 | I31: 134 | J31: 773.58209 | L31: 830 | M31: 772.72727 | N31: 0.074117647
A32: 3349668508587 | B32: RABANNE | C32: Perfumaria/Colonia | D32: 80ml | E32: Rabanne Lady Million Edp 80ml Para Femin | F32: 2 | G32: 5 | H32: 101100 | I32: 173 | J32: 584.39306 | L32: 1233.3333 | M32: 572.94118 | N32: 1.1526352
A33: 4710206002185 | B33: MARURI | C33: Pesca/Nautica | D33: Não identificado no título | E33: Carretilha Maruri Black Tamba Bg 11 Rol; | F33: 1 | G33: 1 | H33: 99700 | I33: 260 | J33: 383.46154 | K33: 383.46154
A34: 7898639692849 | B34: G-TECH | C34: Saude/Bem-estar | D34: Não identificado no título | E34: Termômetro Infravermelho Ultracompacto D | F34: 1 | G34: 1 | H34: 92800 | I34: 1900 | J34: 48.842105 | K34: 48.842105
