Workbook

Sheet Resumo Executivo
B2: Priorização de Entrada em Perfumaria — Top 100 Marcas (Nubmetrics, ago/2026)
B3: Categorias MLB1246 / MLB6284 no Mercado Livre · dados reais de vendas extraídos pelo Nubmetrics
B5: Marcas analisadas | C5: 100
B6: Vendas somadas (top 100 marcas) | C6: =SUM(Dados!F2:F101) -> 193562500
B7: Unidades vendidas (top 100 marcas) | C7: =SUM(Dados!G2:G101) -> 1165718
B8: Marcas do seu mix de nicho já nesta lista | C8: =COUNTIF(Dados!D2:D101,"Sim") -> 3
B10: Achado principal: seu mix de nicho já é validado pelos dados
B11: XERJOFF, NISHANE e PARFUMS DE MARLY — as 3 marcas de nicho que você já definiu para a perfumaria — aparecem no top 100 do Mercado Livre com Saturação Baixa e Tendência Crescendo, e ticket médio entre R$1.500 e R$2.300 por unidade (muito acima da média do mercado, que fica na faixa de R$50-150). Poucos vendedores disputando (28-52), demanda comprovada e posicionamento de alta perfumaria: é exatamente o perfil de 'maior lucro e mais requinte' que você quer, e os dados confirmam que ainda há espaço pra entrar sem brigar de preço com 500 vendedores. SOSPIRO e CREED (mesma faixa de nicho) mostram o mesmo padrão, caso queira ampliar o mix.
B13: Como o modelo de pontuação funciona
B14: Pontuação 0-100 combinando 4 fatores, com pesos que você pode ajustar na aba "Priorização de Entrada" (célula amarela): ticket médio (proxy de lucro/requinte — 35%), poucos vendedores concorrendo (facilidade de entrada com capital de giro limitado — 25%), saturação baixa (espaço de mercado — 20%) e tendência de crescimento — 20%). Não é uma medida de margem real (não temos custo de aquisição nem frete) — é um proxy para ordenar por onde vale mais a pena negociar primeiro.
B16: Ondas de entrada sugeridas (pensando no seu capital de giro)
B17: • | C17: Onda 1 (as 12 melhor pontuadas): negociar/testar primeiro — melhor combinação de ticket alto, pouca concorrência e crescimento. Investimento menor por SKU testado, retorno relativo maior.
B18: • | C18: Onda 2 (próximas 28): fila de espera — bons candidatos, mas com mais concorrência ou ticket mais baixo. Entrar depois que o caixa das primeiras marcas already girar.
B19: • | C19: Onda 3 (as 60 restantes): marcas grandes/saturadas (ex: Natura, O Boticário) ou de menor ticket — exigem mais capital ou brigam mais no preço. Deixar para quando já tiver capital de giro mais folgado.
B21: Como usar este relatório
B22: • | C22: Aba "Priorização de Entrada": a lista pronta, já ordenada pela pontuação, com a onda sugerida na primeira coluna. Linhas verdes = Onda 1. Linhas roxas = já está no seu mix de nicho.
B23: • | C23: Aba "Dados": os 100 registros do Nubmetrics, convertidos para número (Vendas, Unidades, % Catálogo), com a coluna "Posicionamento" — minha classificação de cada marca (Nacional/Massa, Árabe/Import Acessível, Designer/Importado, Alta Perfumaria/Nicho). Marcas que eu não conhecia bem ficaram como "A verificar" — não chutei.
B24: • | C24: Pesos ajustáveis: mude as células amarelas no topo de "Priorização de Entrada" pra dar mais ou menos peso a cada fator — tudo recalcula sozinho.
B26: Limitações
B27: • | C27: Isso é ranking de vendas e concorrência no Mercado Livre — não é sua margem real. Custo de aquisição, frete, imposto e MOQ do fornecedor de cada marca não estão aqui e mudam a conta.
B28: • | C28: "Posicionamento" é minha classificação por conhecimento geral do mercado de perfumaria, não um dado do Nubmetrics — trate como ponto de partida, não como verdade absoluta, principalmente nas marcas marcadas "A verificar".
B29: • | C29: "Ranking de demanda" (coluna da aba Dados) é outra métrica do Nubmetrics que não incorporei na pontuação por não ter certeza da metodologia exata (maioria das marcas aparece como 0) — vale conferir direto na plataforma antes de usar.
B30: • | C30: Retrato de agosto/2026 — sazonalidade (datas comemorativas, por exemplo) pode alterar bastante esse ranking em outros meses.

Sheet Priorização de Entrada
A1: Pesos do modelo (ajuste livremente — a pontuação recalcula sozinha)
A3: Peso: Ticket médio (proxy de lucro/requinte) | B3: 0.35
A4: Peso: Poucos vendedores (facilidade/capital de entrada) | B4: 0.25
A5: Peso: Saturação baixa (espaço de mercado) | B5: 0.2
A6: Peso: Tendência de crescimento | B6: 0.2
A7: Soma dos pesos (deve ser 100%) | B7: =SUM(B3:B6) -> 1
A9: Onda de Entrada | B9: Marca | C9: Posicionamento | D9: Já no seu mix? | E9: Pontuação (0-100) | F9: Ticket Médio (R$) | G9: Nº Vendedores | H9: Saturação | I9: Tendência | J9: Vendas (R$) | K9: Unidades Vendidas | L9: % Catálogo
A10: =IF(1<=12,"Onda 1 — testar agora",IF(1<=40,"Onda 2 — próximos passos","Onda 3 — depois de consolidar")) -> Onda 1 — testar agora | B10: =INDEX(Dados!$B:$B,MATCH(1,Dados!$O:$O,0)) -> CREED | C10: =INDEX(Dados!$C:$C,MATCH(1,Dados!$O:$O,0)) -> Alta Perfumaria/Nicho | D10: =INDEX(Dados!$D:$D,MATCH(1,Dados!$O:$O,0)) -> Não | E10: =INDEX(Dados!$N:$N,MATCH(1,Dados!$O:$O,0)) -> 98.883627 | F10: =INDEX(Dados!$H:$H,MATCH(1,Dados!$O:$O,0)) -> 2290.7407 | G10: =INDEX(Dados!$K:$K,MATCH(1,Dados!$O:$O,0)) -> 33 | H10: =INDEX(Dados!$L:$L,MATCH(1,Dados!$O:$O,0)) -> Baixa | I10: =INDEX(Dados!$I:$I,MATCH(1,Dados!$O:$O,0)) -> Crescendo | J10: =INDEX(Dados!$F:$F,MATCH(1,Dados!$O:$O,0)) -> 371100 | K10: =INDEX(Dados!$G:$G,MATCH(1,Dados!$O:$O,0)) -> 162 | L10: =INDEX(Dados!$J:$J,MATCH(1,Dados!$O:$O,0)) -> 0.7324
A11: =IF(2<=12,"Onda 1 — testar agora",IF(2<=40,"Onda 2 — próximos passos","Onda 3 — depois de consolidar")) -> Onda 1 — testar agora | B11: =INDEX(Dados!$B:$B,MATCH(2,Dados!$O:$O,0)) -> PARFUMS DE MARLY | C11: =INDEX(Dados!$C:$C,MATCH(2,Dados!$O:$O,0)) -> Alta Perfumaria/Nicho | D11: =INDEX(Dados!$D:$D,MATCH(2,Dados!$O:$O,0)) -> Sim | E11: =INDEX(Dados!$N:$N,MATCH(2,Dados!$O:$O,0)) -> 94.224929 | F11: =INDEX(Dados!$H:$H,MATCH(2,Dados!$O:$O,0)) -> 1976.9737 | G11: =INDEX(Dados!$K:$K,MATCH(2,Dados!$O:$O,0)) -> 29 | H11: =INDEX(Dados!$L:$L,MATCH(2,Dados!$O:$O,0)) -> Baixa | I11: =INDEX(Dados!$I:$I,MATCH(2,Dados!$O:$O,0)) -> Crescendo | J11: =INDEX(Dados!$F:$F,MATCH(2,Dados!$O:$O,0)) -> 300500 | K11: =INDEX(Dados!$G:$G,MATCH(2,Dados!$O:$O,0)) -> 152 | L11: =INDEX(Dados!$J:$J,MATCH(2,Dados!$O:$O,0)) -> 0.7123
A12: =IF(3<=12,"Onda 1 — testar agora",IF(3<=40,"Onda 2 — próximos passos","Onda 3 — depois de consolidar")) -> Onda 1 — testar agora | B12: =INDEX(Dados!$B:$B,MATCH(3,Dados!$O:$O,0)) -> NISHANE | C12: =INDEX(Dados!$C:$C,MATCH(3,Dados!$O:$O,0)) -> Alta Perfumaria/Nicho | D12: =INDEX(Dados!$D:$D,MATCH(3,Dados!$O:$O,0)) -> Sim | E12: =INDEX(Dados!$N:$N,MATCH(3,Dados!$O:$O,0)) -> 91.353946 | F12: =INDEX(Dados!$H:$H,MATCH(3,Dados!$O:$O,0)) -> 1786.8545 | G12: =INDEX(Dados!$K:$K,MATCH(3,Dados!$O:$O,0)) -> 28 | H12: =INDEX(Dados!$L:$L,MATCH(3,Dados!$O:$O,0)) -> Baixa | I12: =INDEX(Dados!$I:$I,MATCH(3,Dados!$O:$O,0)) -> Crescendo | J12: =INDEX(Dados!$F:$F,MATCH(3,Dados!$O:$O,0)) -> 380600 | K12: =INDEX(Dados!$G:$G,MATCH(3,Dados!$O:$O,0)) -> 213 | L12: =INDEX(Dados!$J:$J,MATCH(3,Dados!$O:$O,0)) -> 0.7377
A13: =IF(4<=12,"Onda 1 — testar agora",IF(4<=40,"Onda 2 — próximos passos","Onda 3 — depois de consolidar")) -> Onda 1 — testar agora | B13: =INDEX(Dados!$B:$B,MATCH(4,Dados!$O:$O,0)) -> XERJOFF | C13: =INDEX(Dados!$C:$C,MATCH(4,Dados!$O:$O,0)) -> Alta Perfumaria/Nicho | D13: =INDEX(Dados!$D:$D,MATCH(4,Dados!$O:$O,0)) -> Sim | E13: =INDEX(Dados!$N:$N,MATCH(4,Dados!$O:$O,0)) -> 76.838621 | F13: =INDEX(Dados!$H:$H,MATCH(4,Dados!$O:$O,0)) -> 1544.4668 | G13: =INDEX(Dados!$K:$K,MATCH(4,Dados!$O:$O,0)) -> 52 | H13: =INDEX(Dados!$L:$L,MATCH(4,Dados!$O:$O,0)) -> Média | I13: =INDEX(Dados!$I:$I,MATCH(4,Dados!$O:$O,0)) -> Crescendo | J13: =INDEX(Dados!$F:$F,MATCH(4,Dados!$O:$O,0)) -> 767600 | K13: =INDEX(Dados!$G:$G,MATCH(4,Dados!$O:$O,0)) -> 497 | L13: =INDEX(Dados!$J:$J,MATCH(4,Dados!$O:$O,0)) -> 0.7483
A14: =IF(5<=12,"Onda 1 — testar agora",IF(5<=40,"Onda 2 — próximos passos","Onda 3 — depois de consolidar")) -> Onda 1 — testar agora | B14: =INDEX(Dados!$B:$B,MATCH(5,Dados!$O:$O,0)) -> SOSPIRO | C14: =INDEX(Dados!$C:$C,MATCH(5,Dados!$O:$O,0)) -> Alta Perfumaria/Nicho | D14: =INDEX(Dados!$D:$D,MATCH(5,Dados!$O:$O,0)) -> Não | E14: =INDEX(Dados!$N:$N,MATCH(5,Dados!$O:$O,0)) -> 75.120981 | F14: =INDEX(Dados!$H:$H,MATCH(5,Dados!$O:$O,0)) -> 1396.6216 | G14: =INDEX(Dados!$K:$K,MATCH(5,Dados!$O:$O,0)) -> 36 | H14: =INDEX(Dados!$L:$L,MATCH(5,Dados!$O:$O,0)) -> Média | I14: =INDEX(Dados!$I:$I,MATCH(5,Dados!$O:$O,0)) -> Crescendo | J14: =INDEX(Dados!$F:$F,MATCH(5,Dados!$O:$O,0)) -> 826800 | K14: =INDEX(Dados!$G:$G,MATCH(5,Dados!$O:$O,0)) -> 592 | L14: =INDEX(Dados!$J:$J,MATCH(5,Dados!$O:$O,0)) -> 0.6364
A15: =IF(6<=12,"Onda 1 — testar agora",IF(6<=40,"Onda 2 — próximos passos","Onda 3 — depois de consolidar")) -> Onda 1 — testar agora | B15: =INDEX(Dados!$B:$B,MATCH(6,Dados!$O:$O,0)) -> MAISON ASRAR | C15: =INDEX(Dados!$C:$C,MATCH(6,Dados!$O:$O,0)) -> Árabe/Import Acessível | D15: =INDEX(Dados!$D:$D,MATCH(6,Dados!$O:$O,0)) -> Não | E15: =INDEX(Dados!$N:$N,MATCH(6,Dados!$O:$O,0)) -> 68.797449 | F15: =INDEX(Dados!$H:$H,MATCH(6,Dados!$O:$O,0)) -> 385.81818 | G15: =INDEX(Dados!$K:$K,MATCH(6,Dados!$O:$O,0)) -> 62 | H15: =INDEX(Dados!$L:$L,MATCH(6,Dados!$O:$O,0)) -> Baixa | I15: =INDEX(Dados!$I:$I,MATCH(6,Dados!$O:$O,0)) -> Crescendo | J15: =INDEX(Dados!$F:$F,MATCH(6,Dados!$O:$O,0)) -> 424400 | K15: =INDEX(Dados!$G:$G,MATCH(6,Dados!$O:$O,0)) -> 1100 | L15: =INDEX(Dados!$J:$J,MATCH(6,Dados!$O:$O,0)) -> 0.7066
A16: =IF(7<=12,"Onda 1 — testar agora",IF(7<=40,"Onda 2 — próximos passos","Onda 3 — depois de consolidar")) -> Onda 1 — testar agora | B16: =INDEX(Dados!$B:$B,MATCH(7,Dados!$O:$O,0)) -> IN THE BOX | C16: =INDEX(Dados!$C:$C,MATCH(7,Dados!$O:$O,0)) -> A verificar | D16: =INDEX(Dados!$D:$D,MATCH(7,Dados!$O:$O,0)) -> Não | E16: =INDEX(Dados!$N:$N,MATCH(7,Dados!$O:$O,0)) -> 68.263049 | F16: =INDEX(Dados!$H:$H,MATCH(7,Dados!$O:$O,0)) -> 224.63636 | G16: =INDEX(Dados!$K:$K,MATCH(7,Dados!$O:$O,0)) -> 5 | H16: =INDEX(Dados!$L:$L,MATCH(7,Dados!$O:$O,0)) -> Baixa | I16: =INDEX(Dados!$I:$I,MATCH(7,Dados!$O:$O,0)) -> Crescendo | J16: =INDEX(Dados!$F:$F,MATCH(7,Dados!$O:$O,0)) -> 247100 | K16: =INDEX(Dados!$G:$G,MATCH(7,Dados!$O:$O,0)) -> 1100 | L16: =INDEX(Dados!$J:$J,MATCH(7,Dados!$O:$O,0)) -> 0.2176
A17: =IF(8<=12,"Onda 1 — testar agora",IF(8<=40,"Onda 2 — próximos passos","Onda 3 — depois de consolidar")) -> Onda 1 — testar agora | B17: =INDEX(Dados!$B:$B,MATCH(8,Dados!$O:$O,0)) -> AL HARAMAIN | C17: =INDEX(Dados!$C:$C,MATCH(8,Dados!$O:$O,0)) -> Árabe/Import Acessível | D17: =INDEX(Dados!$D:$D,MATCH(8,Dados!$O:$O,0)) -> Não | E17: =INDEX(Dados!$N:$N,MATCH(8,Dados!$O:$O,0)) -> 67.607294 | F17: =INDEX(Dados!$H:$H,MATCH(8,Dados!$O:$O,0)) -> 321.20766 | G17: =INDEX(Dados!$K:$K,MATCH(8,Dados!$O:$O,0)) -> 68 | H17: =INDEX(Dados!$L:$L,MATCH(8,Dados!$O:$O,0)) -> Baixa | I17: =INDEX(Dados!$I:$I,MATCH(8,Dados!$O:$O,0)) -> Crescendo | J17: =INDEX(Dados!$F:$F,MATCH(8,Dados!$O:$O,0)) -> 218100 | K17: =INDEX(Dados!$G:$G,MATCH(8,Dados!$O:$O,0)) -> 679 | L17: =INDEX(Dados!$J:$J,MATCH(8,Dados!$O:$O,0)) -> 0.7247
A18: =IF(9<=12,"Onda 1 — testar agora",IF(9<=40,"Onda 2 — próximos passos","Onda 3 — depois de consolidar")) -> Onda 1 — testar agora | B18: =INDEX(Dados!$B:$B,MATCH(9,Dados!$O:$O,0)) -> LESCENT | C18: =INDEX(Dados!$C:$C,MATCH(9,Dados!$O:$O,0)) -> A verificar | D18: =INDEX(Dados!$D:$D,MATCH(9,Dados!$O:$O,0)) -> Não | E18: =INDEX(Dados!$N:$N,MATCH(9,Dados!$O:$O,0)) -> 65.705103 | F18: =INDEX(Dados!$H:$H,MATCH(9,Dados!$O:$O,0)) -> 59.433566 | G18: =INDEX(Dados!$K:$K,MATCH(9,Dados!$O:$O,0)) -> 6 | H18: =INDEX(Dados!$L:$L,MATCH(9,Dados!$O:$O,0)) -> Baixa | I18: =INDEX(Dados!$I:$I,MATCH(9,Dados!$O:$O,0)) -> Crescendo | J18: =INDEX(Dados!$F:$F,MATCH(9,Dados!$O:$O,0)) -> 849900 | K18: =INDEX(Dados!$G:$G,MATCH(9,Dados!$O:$O,0)) -> 14300 | L18: =INDEX(Dados!$J:$J,MATCH(9,Dados!$O:$O,0)) -> 0.5215
A19: =IF(10<=12,"Onda 1 — testar agora",IF(10<=40,"Onda 2 — próximos passos","Onda 3 — depois de consolidar")) -> Onda 1 — testar agora | B19: =INDEX(Dados!$B:$B,MATCH(10,Dados!$O:$O,0)) -> FERRARI | C19: =INDEX(Dados!$C:$C,MATCH(10,Dados!$O:$O,0)) -> Designer/Importado | D19: =INDEX(Dados!$D:$D,MATCH(10,Dados!$O:$O,0)) -> Não | E19: =INDEX(Dados!$N:$N,MATCH(10,Dados!$O:$O,0)) -> 65.348606 | F19: =INDEX(Dados!$H:$H,MATCH(10,Dados!$O:$O,0)) -> 193.30435 | G19: =INDEX(Dados!$K:$K,MATCH(10,Dados!$O:$O,0)) -> 77 | H19: =INDEX(Dados!$L:$L,MATCH(10,Dados!$O:$O,0)) -> Baixa | I19: =INDEX(Dados!$I:$I,MATCH(10,Dados!$O:$O,0)) -> Crescendo | J19: =INDEX(Dados!$F:$F,MATCH(10,Dados!$O:$O,0)) -> 444600 | K19: =INDEX(Dados!$G:$G,MATCH(10,Dados!$O:$O,0)) -> 2300 | L19: =INDEX(Dados!$J:$J,MATCH(10,Dados!$O:$O,0)) -> 0.6234
A20: =IF(11<=12,"Onda 1 — testar agora",IF(11<=40,"Onda 2 — próximos passos","Onda 3 — depois de consolidar")) -> Onda 1 — testar agora | B20: =INDEX(Dados!$B:$B,MATCH(11,Dados!$O:$O,0)) -> GRANADO | C20: =INDEX(Dados!$C:$C,MATCH(11,Dados!$O:$O,0)) -> Nacional/Massa | D20: =INDEX(Dados!$D:$D,MATCH(11,Dados!$O:$O,0)) -> Não | E20: =INDEX(Dados!$N:$N,MATCH(11,Dados!$O:$O,0)) -> 65.152245 | F20: =INDEX(Dados!$H:$H,MATCH(11,Dados!$O:$O,0)) -> 182.66667 | G20: =INDEX(Dados!$K:$K,MATCH(11,Dados!$O:$O,0)) -> 78 | H20: =INDEX(Dados!$L:$L,MATCH(11,Dados!$O:$O,0)) -> Baixa | I20: =INDEX(Dados!$I:$I,MATCH(11,Dados!$O:$O,0)) -> Crescendo | J20: =INDEX(Dados!$F:$F,MATCH(11,Dados!$O:$O,0)) -> 602800 | K20: =INDEX(Dados!$G:$G,MATCH(11,Dados!$O:$O,0)) -> 3300 | L20: =INDEX(Dados!$J:$J,MATCH(11,Dados!$O:$O,0)) -> 0.6229
A21: =IF(12<=12,"Onda 1 — testar agora",IF(12<=40,"Onda 2 — próximos passos","Onda 3 — depois de consolidar")) -> Onda 1 — testar agora | B21: =INDEX(Dados!$B:$B,MATCH(12,Dados!$O:$O,0)) -> NARCISO RODRIGUEZ | C21: =INDEX(Dados!$C:$C,MATCH(12,Dados!$O:$O,0)) -> Designer/Importado | D21: =INDEX(Dados!$D:$D,MATCH(12,Dados!$O:$O,0)) -> Não | E21: =INDEX(Dados!$N:$N,MATCH(12,Dados!$O:$O,0)) -> 63.743301 | F21: =INDEX(Dados!$H:$H,MATCH(12,Dados!$O:$O,0)) -> 671.88264 | G21: =INDEX(Dados!$K:$K,MATCH(12,Dados!$O:$O,0)) -> 45 | H21: =INDEX(Dados!$L:$L,MATCH(12,Dados!$O:$O,0)) -> Média | I21: =INDEX(Dados!$I:$I,MATCH(12,Dados!$O:$O,0)) -> Crescendo | J21: =INDEX(Dados!$F:$F,MATCH(12,Dados!$O:$O,0)) -> 274800 | K21: =INDEX(Dados!$G:$G,MATCH(12,Dados!$O:$O,0)) -> 409 | L21: =INDEX(Dados!$J:$J,MATCH(12,Dados!$O:$O,0)) -> 0.6547
A22: =IF(13<=12,"Onda 1 — testar agora",IF(13<=40,"Onda 2 — próximos passos","Onda 3 — depois de consolidar")) -> Onda 2 — próximos passos | B22: =INDEX(Dados!$B:$B,MATCH(13,Dados!$O:$O,0)) -> BRAND COLLECTION | C22: =INDEX(Dados!$C:$C,MATCH(13,Dados!$O:$O,0)) -> Nacional/Contratipo | D22: =INDEX(Dados!$D:$D,MATCH(13,Dados!$O:$O,0)) -> Não | E22: =INDEX(Dados!$N:$N,MATCH(13,Dados!$O:$O,0)) -> 63.510099 | F22: =INDEX(Dados!$H:$H,MATCH(13,Dados!$O:$O,0)) -> 57.47561 | G22: =INDEX(Dados!$K:$K,MATCH(13,Dados!$O:$O,0)) -> 70 | H22: =INDEX(Dados!$L:$L,MATCH(13,Dados!$O:$O,0)) -> Baixa | I22: =INDEX(Dados!$I:$I,MATCH(13,Dados!$O:$O,0)) -> Crescendo | J22: =INDEX(Dados!$F:$F,MATCH(13,Dados!$O:$O,0)) -> 471300 | K22: =INDEX(Dados!$G:$G,MATCH(13,Dados!$O:$O,0)) -> 8200 | L22: =INDEX(Dados!$J:$J,MATCH(13,Dados!$O:$O,0)) -> 0.6627
A23: =IF(14<=12,"Onda 1 — testar agora",IF(14<=40,"Onda 2 — próximos passos","Onda 3 — depois de consolidar")) -> Onda 2 — próximos passos | B23: =INDEX(Dados!$B:$B,MATCH(14,Dados!$O:$O,0)) -> BVLGARI | C23: =INDEX(Dados!$C:$C,MATCH(14,Dados!$O:$O,0)) -> Designer/Importado Premium | D23: =INDEX(Dados!$D:$D,MATCH(14,Dados!$O:$O,0)) -> Não | E23: =INDEX(Dados!$N:$N,MATCH(14,Dados!$O:$O,0)) -> 62.719233 | F23: =INDEX(Dados!$H:$H,MATCH(14,Dados!$O:$O,0)) -> 644.71204 | G23: =INDEX(Dados!$K:$K,MATCH(14,Dados!$O:$O,0)) -> 63 | H23: =INDEX(Dados!$L:$L,MATCH(14,Dados!$O:$O,0)) -> Média | I23: =INDEX(Dados!$I:$I,MATCH(14,Dados!$O:$O,0)) -> Crescendo | J23: =INDEX(Dados!$F:$F,MATCH(14,Dados!$O:$O,0)) -> 615700 | K23: =INDEX(Dados!$G:$G,MATCH(14,Dados!$O:$O,0)) -> 955 | L23: =INDEX(Dados!$J:$J,MATCH(14,Dados!$O:$O,0)) -> 0.6653
A24: =IF(15<=12,"Onda 1 — testar agora",IF(15<=40,"Onda 2 — próximos passos","Onda 3 — depois de consolidar")) -> Onda 2 — próximos passos | B24: =INDEX(Dados!$B:$B,MATCH(15,Dados!$O:$O,0)) -> CHANEL | C24: =INDEX(Dados!$C:$C,MATCH(15,Dados!$O:$O,0)) -> Designer/Importado Premium | D24: =INDEX(Dados!$D:$D,MATCH(15,Dados!$O:$O,0)) -> Não | E24: =INDEX(Dados!$N:$N,MATCH(15,Dados!$O:$O,0)) -> 58.553596 | F24: =INDEX(Dados!$H:$H,MATCH(15,Dados!$O:$O,0)) -> 1000 | G24: =INDEX(Dados!$K:$K,MATCH(15,Dados!$O:$O,0)) -> 51 | H24: =INDEX(Dados!$L:$L,MATCH(15,Dados!$O:$O,0)) -> Baixa | I24: =INDEX(Dados!$I:$I,MATCH(15,Dados!$O:$O,0)) -> Diminuindo | J24: =INDEX(Dados!$F:$F,MATCH(15,Dados!$O:$O,0)) -> 1400000 | K24: =INDEX(Dados!$G:$G,MATCH(15,Dados!$O:$O,0)) -> 1400 | L24: =INDEX(Dados!$J:$J,MATCH(15,Dados!$O:$O,0)) -> 0.6857
A25: =IF(16<=12,"Onda 1 — testar agora",IF(16<=40,"Onda 2 — próximos passos","Onda 3 — depois de consolidar")) -> Onda 2 — próximos passos | B25: =INDEX(Dados!$B:$B,MATCH(16,Dados!$O:$O,0)) -> ISSEY MIYAKE | C25: =INDEX(Dados!$C:$C,MATCH(16,Dados!$O:$O,0)) -> Designer/Importado | D25: =INDEX(Dados!$D:$D,MATCH(16,Dados!$O:$O,0)) -> Não | E25: =INDEX(Dados!$N:$N,MATCH(16,Dados!$O:$O,0)) -> 58.311119 | F25: =INDEX(Dados!$H:$H,MATCH(16,Dados!$O:$O,0)) -> 387.2 | G25: =INDEX(Dados!$K:$K,MATCH(16,Dados!$O:$O,0)) -> 77 | H25: =INDEX(Dados!$L:$L,MATCH(16,Dados!$O:$O,0)) -> Média | I25: =INDEX(Dados!$I:$I,MATCH(16,Dados!$O:$O,0)) -> Crescendo | J25: =INDEX(Dados!$F:$F,MATCH(16,Dados!$O:$O,0)) -> 968000 | K25: =INDEX(Dados!$G:$G,MATCH(16,Dados!$O:$O,0)) -> 2500 | L25: =INDEX(Dados!$J:$J,MATCH(16,Dados!$O:$O,0)) -> 0.7072
A26: =IF(17<=12,"Onda 1 — testar agora",IF(17<=40,"Onda 2 — próximos passos","Onda 3 — depois de consolidar")) -> Onda 2 — próximos passos | B26: =INDEX(Dados!$B:$B,MATCH(17,Dados!$O:$O,0)) -> MOSCHINO | C26: =INDEX(Dados!$C:$C,MATCH(17,Dados!$O:$O,0)) -> Designer/Importado | D26: =INDEX(Dados!$D:$D,MATCH(17,Dados!$O:$O,0)) -> Não | E26: =INDEX(Dados!$N:$N,MATCH(17,Dados!$O:$O,0)) -> 57.965553 | F26: =INDEX(Dados!$H:$H,MATCH(17,Dados!$O:$O,0)) -> 322.51429 | G26: =INDEX(Dados!$K:$K,MATCH(17,Dados!$O:$O,0)) -> 58 | H26: =INDEX(Dados!$L:$L,MATCH(17,Dados!$O:$O,0)) -> Média | I26: =INDEX(Dados!$I:$I,MATCH(17,Dados!$O:$O,0)) -> Crescendo | J26: =INDEX(Dados!$F:$F,MATCH(17,Dados!$O:$O,0)) -> 282200 | K26: =INDEX(Dados!$G:$G,MATCH(17,Dados!$O:$O,0)) -> 875 | L26: =INDEX(Dados!$J:$J,MATCH(17,Dados!$O:$O,0)) -> 0.7136
A27: =IF(18<=12,"Onda 1 — testar agora",IF(18<=40,"Onda 2 — próximos passos","Onda 3 — depois de consolidar")) -> Onda 2 — próximos passos | B27: =INDEX(Dados!$B:$B,MATCH(18,Dados!$O:$O,0)) -> TOMMY HILFIGER | C27: =INDEX(Dados!$C:$C,MATCH(18,Dados!$O:$O,0)) -> Designer/Importado | D27: =INDEX(Dados!$D:$D,MATCH(18,Dados!$O:$O,0)) -> Não | E27: =INDEX(Dados!$N:$N,MATCH(18,Dados!$O:$O,0)) -> 57.628607 | F27: =INDEX(Dados!$H:$H,MATCH(18,Dados!$O:$O,0)) -> 271.67756 | G27: =INDEX(Dados!$K:$K,MATCH(18,Dados!$O:$O,0)) -> 45 | H27: =INDEX(Dados!$L:$L,MATCH(18,Dados!$O:$O,0)) -> Média | I27: =INDEX(Dados!$I:$I,MATCH(18,Dados!$O:$O,0)) -> Crescendo | J27: =INDEX(Dados!$F:$F,MATCH(18,Dados!$O:$O,0)) -> 249400 | K27: =INDEX(Dados!$G:$G,MATCH(18,Dados!$O:$O,0)) -> 918 | L27: =INDEX(Dados!$J:$J,MATCH(18,Dados!$O:$O,0)) -> 0.6894
A28: =IF(19<=12,"Onda 1 — testar agora",IF(19<=40,"Onda 2 — próximos passos","Onda 3 — depois de consolidar")) -> Onda 2 — próximos passos | B28: =INDEX(Dados!$B:$B,MATCH(19,Dados!$O:$O,0)) -> LAB 8 FRAGRANCES | C28: =INDEX(Dados!$C:$C,MATCH(19,Dados!$O:$O,0)) -> A verificar | D28: =INDEX(Dados!$D:$D,MATCH(19,Dados!$O:$O,0)) -> Não | E28: =INDEX(Dados!$N:$N,MATCH(19,Dados!$O:$O,0)) -> 56.546241 | F28: =INDEX(Dados!$H:$H,MATCH(19,Dados!$O:$O,0)) -> 178.69565 | G28: =INDEX(Dados!$K:$K,MATCH(19,Dados!$O:$O,0)) -> 35 | H28: =INDEX(Dados!$L:$L,MATCH(19,Dados!$O:$O,0)) -> Média | I28: =INDEX(Dados!$I:$I,MATCH(19,Dados!$O:$O,0)) -> Crescendo | J28: =INDEX(Dados!$F:$F,MATCH(19,Dados!$O:$O,0)) -> 411000 | K28: =INDEX(Dados!$G:$G,MATCH(19,Dados!$O:$O,0)) -> 2300 | L28: =INDEX(Dados!$J:$J,MATCH(19,Dados!$O:$O,0)) -> 0.5849
A29: =IF(20<=12,"Onda 1 — testar agora",IF(20<=40,"Onda 2 — próximos passos","Onda 3 — depois de consolidar")) -> Onda 2 — próximos passos | B29: =INDEX(Dados!$B:$B,MATCH(20,Dados!$O:$O,0)) -> ANIMALE | C29: =INDEX(Dados!$C:$C,MATCH(20,Dados!$O:$O,0)) -> Designer/Importado | D29: =INDEX(Dados!$D:$D,MATCH(20,Dados!$O:$O,0)) -> Não | E29: =INDEX(Dados!$N:$N,MATCH(20,Dados!$O:$O,0)) -> 55.721002 | F29: =INDEX(Dados!$H:$H,MATCH(20,Dados!$O:$O,0)) -> 233.17647 | G29: =INDEX(Dados!$K:$K,MATCH(20,Dados!$O:$O,0)) -> 84 | H29: =INDEX(Dados!$L:$L,MATCH(20,Dados!$O:$O,0)) -> Média | I29: =INDEX(Dados!$I:$I,MATCH(20,Dados!$O:$O,0)) -> Crescendo | J29: =INDEX(Dados!$F:$F,MATCH(20,Dados!$O:$O,0)) -> 396400 | K29: =INDEX(Dados!$G:$G,MATCH(20,Dados!$O:$O,0)) -> 1700 | L29: =INDEX(Dados!$J:$J,MATCH(20,Dados!$O:$O,0)) -> 0.5472
A30: =IF(21<=12,"Onda 1 — testar agora",IF(21<=40,"Onda 2 — próximos passos","Onda 3 — depois de consolidar")) -> Onda 2 — próximos passos | B30: =INDEX(Dados!$B:$B,MATCH(21,Dados!$O:$O,0)) -> PARIS CORNER | C30: =INDEX(Dados!$C:$C,MATCH(21,Dados!$O:$O,0)) -> Árabe/Import Acessível | D30: =INDEX(Dados!$D:$D,MATCH(21,Dados!$O:$O,0)) -> Não | E30: =INDEX(Dados!$N:$N,MATCH(21,Dados!$O:$O,0)) -> 55.680433 | F30: =INDEX(Dados!$H:$H,MATCH(21,Dados!$O:$O,0)) -> 265.94737 | G30: =INDEX(Dados!$K:$K,MATCH(21,Dados!$O:$O,0)) -> 100 | H30: =INDEX(Dados!$L:$L,MATCH(21,Dados!$O:$O,0)) -> Média | I30: =INDEX(Dados!$I:$I,MATCH(21,Dados!$O:$O,0)) -> Crescendo | J30: =INDEX(Dados!$F:$F,MATCH(21,Dados!$O:$O,0)) -> 505300 | K30: =INDEX(Dados!$G:$G,MATCH(21,Dados!$O:$O,0)) -> 1900 | L30: =INDEX(Dados!$J:$J,MATCH(21,Dados!$O:$O,0)) -> 0.7238
A31: =IF(22<=12,"Onda 1 — testar agora",IF(22<=40,"Onda 2 — próximos passos","Onda 3 — depois de consolidar")) -> Onda 2 — próximos passos | B31: =INDEX(Dados!$B:$B,MATCH(22,Dados!$O:$O,0)) -> AFNAN | C31: =INDEX(Dados!$C:$C,MATCH(22,Dados!$O:$O,0)) -> Árabe/Import Acessível | D31: =INDEX(Dados!$D:$D,MATCH(22,Dados!$O:$O,0)) -> Não | E31: =INDEX(Dados!$N:$N,MATCH(22,Dados!$O:$O,0)) -> 55.086201 | F31: =INDEX(Dados!$H:$H,MATCH(22,Dados!$O:$O,0)) -> 333.33333 | G31: =INDEX(Dados!$K:$K,MATCH(22,Dados!$O:$O,0)) -> 148 | H31: =INDEX(Dados!$L:$L,MATCH(22,Dados!$O:$O,0)) -> Média | I31: =INDEX(Dados!$I:$I,MATCH(22,Dados!$O:$O,0)) -> Crescendo | J31: =INDEX(Dados!$F:$F,MATCH(22,Dados!$O:$O,0)) -> 1600000 | K31: =INDEX(Dados!$G:$G,MATCH(22,Dados!$O:$O,0)) -> 4800 | L31: =INDEX(Dados!$J:$J,MATCH(22,Dados!$O:$O,0)) -> 0.6917
A32: =IF(23<=12,"Onda 1 — testar agora",IF(23<=40,"Onda 2 — próximos passos","Onda 3 — depois de consolidar")) -> Onda 2 — próximos passos | B32: =INDEX(Dados!$B:$B,MATCH(23,Dados!$O:$O,0)) -> RAYHAAN | C32: =INDEX(Dados!$C:$C,MATCH(23,Dados!$O:$O,0)) -> Árabe/Import Acessível | D32: =INDEX(Dados!$D:$D,MATCH(23,Dados!$O:$O,0)) -> Não | E32: =INDEX(Dados!$N:$N,MATCH(23,Dados!$O:$O,0)) -> 54.947175 | F32: =INDEX(Dados!$H:$H,MATCH(23,Dados!$O:$O,0)) -> 266.66667 | G32: =INDEX(Dados!$K:$K,MATCH(23,Dados!$O:$O,0)) -> 122 | H32: =INDEX(Dados!$L:$L,MATCH(23,Dados!$O:$O,0)) -> Média | I32: =INDEX(Dados!$I:$I,MATCH(23,Dados!$O:$O,0)) -> Crescendo | J32: =INDEX(Dados!$F:$F,MATCH(23,Dados!$O:$O,0)) -> 1200000 | K32: =INDEX(Dados!$G:$G,MATCH(23,Dados!$O:$O,0)) -> 4500 | L32: =INDEX(Dados!$J:$J,MATCH(23,Dados!$O:$O,0)) -> 0.6679
A33: =IF(24<=12,"Onda 1 — testar agora",IF(24<=40,"Onda 2 — próximos passos","Onda 3 — depois de consolidar")) -> Onda 2 — próximos passos | B33: =INDEX(Dados!$B:$B,MATCH(24,Dados!$O:$O,0)) -> RASASI | C33: =INDEX(Dados!$C:$C,MATCH(24,Dados!$O:$O,0)) -> Árabe/Import Acessível | D33: =INDEX(Dados!$D:$D,MATCH(24,Dados!$O:$O,0)) -> Não | E33: =INDEX(Dados!$N:$N,MATCH(24,Dados!$O:$O,0)) -> 54.722752 | F33: =INDEX(Dados!$H:$H,MATCH(24,Dados!$O:$O,0)) -> 258.62069 | G33: =INDEX(Dados!$K:$K,MATCH(24,Dados!$O:$O,0)) -> 125 | H33: =INDEX(Dados!$L:$L,MATCH(24,Dados!$O:$O,0)) -> Média | I33: =INDEX(Dados!$I:$I,MATCH(24,Dados!$O:$O,0)) -> Crescendo | J33: =INDEX(Dados!$F:$F,MATCH(24,Dados!$O:$O,0)) -> 1500000 | K33: =INDEX(Dados!$G:$G,MATCH(24,Dados!$O:$O,0)) -> 5800 | L33: =INDEX(Dados!$J:$J,MATCH(24,Dados!$O:$O,0)) -> 0.6473
A34: =IF(25<=12,"Onda 1 — testar agora",IF(25<=40,"Onda 2 — próximos passos","Onda 3 — depois de consolidar")) -> Onda 2 — próximos passos | B34: =INDEX(Dados!$B:$B,MATCH(25,Dados!$O:$O,0)) -> PHEBO | C34: =INDEX(Dados!$C:$C,MATCH(25,Dados!$O:$O,0)) -> Nacional/Massa | D34: =INDEX(Dados!$D:$D,MATCH(25,Dados!$O:$O,0)) -> Não | E34: =INDEX(Dados!$N:$N,MATCH(25,Dados!$O:$O,0)) -> 54.597765 | F34: =INDEX(Dados!$H:$H,MATCH(25,Dados!$O:$O,0)) -> 106.52174 | G34: =INDEX(Dados!$K:$K,MATCH(25,Dados!$O:$O,0)) -> 60 | H34: =INDEX(Dados!$L:$L,MATCH(25,Dados!$O:$O,0)) -> Média | I34: =INDEX(Dados!$I:$I,MATCH(25,Dados!$O:$O,0)) -> Crescendo | J34: =INDEX(Dados!$F:$F,MATCH(25,Dados!$O:$O,0)) -> 245000 | K34: =INDEX(Dados!$G:$G,MATCH(25,Dados!$O:$O,0)) -> 2300 | L34: =INDEX(Dados!$J:$J,MATCH(25,Dados!$O:$O,0)) -> 0.5217
A35: =IF(26<=12,"Onda 1 — testar agora",IF(26<=40,"Onda 2 — próximos passos","Onda 3 — depois de consolidar")) -> Onda 2 — próximos passos | B35: =INDEX(Dados!$B:$B,MATCH(26,Dados!$O:$O,0)) -> DIOR | C35: =INDEX(Dados!$C:$C,MATCH(26,Dados!$O:$O,0)) -> Designer/Importado Premium | D35: =INDEX(Dados!$D:$D,MATCH(26,Dados!$O:$O,0)) -> Não | E35: =INDEX(Dados!$N:$N,MATCH(26,Dados!$O:$O,0)) -> 54.278718 | F35: =INDEX(Dados!$H:$H,MATCH(26,Dados!$O:$O,0)) -> 777.77778 | G35: =INDEX(Dados!$K:$K,MATCH(26,Dados!$O:$O,0)) -> 77 | H35: =INDEX(Dados!$L:$L,MATCH(26,Dados!$O:$O,0)) -> Baixa | I35: =INDEX(Dados!$I:$I,MATCH(26,Dados!$O:$O,0)) -> Diminuindo | J35: =INDEX(Dados!$F:$F,MATCH(26,Dados!$O:$O,0)) -> 2100000 | K35: =INDEX(Dados!$G:$G,MATCH(26,Dados!$O:$O,0)) -> 2700 | L35: =INDEX(Dados!$J:$J,MATCH(26,Dados!$O:$O,0)) -> 0.8113
A36: =IF(27<=12,"Onda 1 — testar agora",IF(27<=40,"Onda 2 — próximos passos","Onda 3 — depois de consolidar")) -> Onda 2 — próximos passos | B36: =INDEX(Dados!$B:$B,MATCH(27,Dados!$O:$O,0)) -> JEAN PAUL GAULTIER | C36: =INDEX(Dados!$C:$C,MATCH(27,Dados!$O:$O,0)) -> Designer/Importado | D36: =INDEX(Dados!$D:$D,MATCH(27,Dados!$O:$O,0)) -> Não | E36: =INDEX(Dados!$N:$N,MATCH(27,Dados!$O:$O,0)) -> 53.848123 | F36: =INDEX(Dados!$H:$H,MATCH(27,Dados!$O:$O,0)) -> 638.88889 | G36: =INDEX(Dados!$K:$K,MATCH(27,Dados!$O:$O,0)) -> 27 | H36: =INDEX(Dados!$L:$L,MATCH(27,Dados!$O:$O,0)) -> Alta | I36: =INDEX(Dados!$I:$I,MATCH(27,Dados!$O:$O,0)) -> Crescendo | J36: =INDEX(Dados!$F:$F,MATCH(27,Dados!$O:$O,0)) -> 4600000 | K36: =INDEX(Dados!$G:$G,MATCH(27,Dados!$O:$O,0)) -> 7200 | L36: =INDEX(Dados!$J:$J,MATCH(27,Dados!$O:$O,0)) -> 0.7093
A37: =IF(28<=12,"Onda 1 — testar agora",IF(28<=40,"Onda 2 — próximos passos","Onda 3 — depois de consolidar")) -> Onda 2 — próximos passos | B37: =INDEX(Dados!$B:$B,MATCH(28,Dados!$O:$O,0)) -> ERIAN | C37: =INDEX(Dados!$C:$C,MATCH(28,Dados!$O:$O,0)) -> A verificar | D37: =INDEX(Dados!$D:$D,MATCH(28,Dados!$O:$O,0)) -> Não | E37: =INDEX(Dados!$N:$N,MATCH(28,Dados!$O:$O,0)) -> 53.72241 | F37: =INDEX(Dados!$H:$H,MATCH(28,Dados!$O:$O,0)) -> 575.30769 | G37: =INDEX(Dados!$K:$K,MATCH(28,Dados!$O:$O,0)) -> 2 | H37: =INDEX(Dados!$L:$L,MATCH(28,Dados!$O:$O,0)) -> Alta | I37: =INDEX(Dados!$I:$I,MATCH(28,Dados!$O:$O,0)) -> Crescendo | J37: =INDEX(Dados!$F:$F,MATCH(28,Dados!$O:$O,0)) -> 747900 | K37: =INDEX(Dados!$G:$G,MATCH(28,Dados!$O:$O,0)) -> 1300 | L37: =INDEX(Dados!$J:$J,MATCH(28,Dados!$O:$O,0)) -> 0.8462
A38: =IF(29<=12,"Onda 1 — testar agora",IF(29<=40,"Onda 2 — próximos passos","Onda 3 — depois de consolidar")) -> Onda 2 — próximos passos | B38: =INDEX(Dados!$B:$B,MATCH(29,Dados!$O:$O,0)) -> ARMANI BEAUTY | C38: =INDEX(Dados!$C:$C,MATCH(29,Dados!$O:$O,0)) -> Designer/Importado | D38: =INDEX(Dados!$D:$D,MATCH(29,Dados!$O:$O,0)) -> Não | E38: =INDEX(Dados!$N:$N,MATCH(29,Dados!$O:$O,0)) -> 53.70694 | F38: =INDEX(Dados!$H:$H,MATCH(29,Dados!$O:$O,0)) -> 585.36585 | G38: =INDEX(Dados!$K:$K,MATCH(29,Dados!$O:$O,0)) -> 7 | H38: =INDEX(Dados!$L:$L,MATCH(29,Dados!$O:$O,0)) -> Alta | I38: =INDEX(Dados!$I:$I,MATCH(29,Dados!$O:$O,0)) -> Crescendo | J38: =INDEX(Dados!$F:$F,MATCH(29,Dados!$O:$O,0)) -> 2400000 | K38: =INDEX(Dados!$G:$G,MATCH(29,Dados!$O:$O,0)) -> 4100 | L38: =INDEX(Dados!$J:$J,MATCH(29,Dados!$O:$O,0)) -> 0.5539
A39: =IF(30<=12,"Onda 1 — testar agora",IF(30<=40,"Onda 2 — próximos passos","Onda 3 — depois de consolidar")) -> Onda 2 — próximos passos | B39: =INDEX(Dados!$B:$B,MATCH(30,Dados!$O:$O,0)) -> PRADA | C39: =INDEX(Dados!$C:$C,MATCH(30,Dados!$O:$O,0)) -> Designer/Importado | D39: =INDEX(Dados!$D:$D,MATCH(30,Dados!$O:$O,0)) -> Não | E39: =INDEX(Dados!$N:$N,MATCH(30,Dados!$O:$O,0)) -> 53.666697 | F39: =INDEX(Dados!$H:$H,MATCH(30,Dados!$O:$O,0)) -> 722.22222 | G39: =INDEX(Dados!$K:$K,MATCH(30,Dados!$O:$O,0)) -> 70 | H39: =INDEX(Dados!$L:$L,MATCH(30,Dados!$O:$O,0)) -> Média | I39: =INDEX(Dados!$I:$I,MATCH(30,Dados!$O:$O,0)) -> Estável | J39: =INDEX(Dados!$F:$F,MATCH(30,Dados!$O:$O,0)) -> 1300000 | K39: =INDEX(Dados!$G:$G,MATCH(30,Dados!$O:$O,0)) -> 1800 | L39: =INDEX(Dados!$J:$J,MATCH(30,Dados!$O:$O,0)) -> 0.7171
A40: =IF(31<=12,"Onda 1 — testar agora",IF(31<=40,"Onda 2 — próximos passos","Onda 3 — depois de consolidar")) -> Onda 2 — próximos passos | B40: =INDEX(Dados!$B:$B,MATCH(31,Dados!$O:$O,0)) -> RABANNE | C40: =INDEX(Dados!$C:$C,MATCH(31,Dados!$O:$O,0)) -> Designer/Importado | D40: =INDEX(Dados!$D:$D,MATCH(31,Dados!$O:$O,0)) -> Não | E40: =INDEX(Dados!$N:$N,MATCH(31,Dados!$O:$O,0)) -> 52.694697 | F40: =INDEX(Dados!$H:$H,MATCH(31,Dados!$O:$O,0)) -> 574.46809 | G40: =INDEX(Dados!$K:$K,MATCH(31,Dados!$O:$O,0)) -> 32 | H40: =INDEX(Dados!$L:$L,MATCH(31,Dados!$O:$O,0)) -> Média | I40: =INDEX(Dados!$I:$I,MATCH(31,Dados!$O:$O,0)) -> Estável | J40: =INDEX(Dados!$F:$F,MATCH(31,Dados!$O:$O,0)) -> 8100000 | K40: =INDEX(Dados!$G:$G,MATCH(31,Dados!$O:$O,0)) -> 14100 | L40: =INDEX(Dados!$J:$J,MATCH(31,Dados!$O:$O,0)) -> 0.6857
A41: =IF(32<=12,"Onda 1 — testar agora",IF(32<=40,"Onda 2 — próximos passos","Onda 3 — depois de consolidar")) -> Onda 2 — próximos passos | B41: =INDEX(Dados!$B:$B,MATCH(32,Dados!$O:$O,0)) -> FRENCH AVENUE | C41: =INDEX(Dados!$C:$C,MATCH(32,Dados!$O:$O,0)) -> Árabe/Import Acessível (a verificar) | D41: =INDEX(Dados!$D:$D,MATCH(32,Dados!$O:$O,0)) -> Não | E41: =INDEX(Dados!$N:$N,MATCH(32,Dados!$O:$O,0)) -> 52.29254 | F41: =INDEX(Dados!$H:$H,MATCH(32,Dados!$O:$O,0)) -> 307.69231 | G41: =INDEX(Dados!$K:$K,MATCH(32,Dados!$O:$O,0)) -> 219 | H41: =INDEX(Dados!$L:$L,MATCH(32,Dados!$O:$O,0)) -> Média | I41: =INDEX(Dados!$I:$I,MATCH(32,Dados!$O:$O,0)) -> Crescendo | J41: =INDEX(Dados!$F:$F,MATCH(32,Dados!$O:$O,0)) -> 2400000 | K41: =INDEX(Dados!$G:$G,MATCH(32,Dados!$O:$O,0)) -> 7800 | L41: =INDEX(Dados!$J:$J,MATCH(32,Dados!$O:$O,0)) -> 0.7042
A42: =IF(33<=12,"Onda 1 — testar agora",IF(33<=40,"Onda 2 — próximos passos","Onda 3 — depois de consolidar")) -> Onda 2 — próximos passos | B42: =INDEX(Dados!$B:$B,MATCH(33,Dados!$O:$O,0)) -> YVES SAINT LAURENT | C42: =INDEX(Dados!$C:$C,MATCH(33,Dados!$O:$O,0)) -> Designer/Importado | D42: =INDEX(Dados!$D:$D,MATCH(33,Dados!$O:$O,0)) -> Não | E42: =INDEX(Dados!$N:$N,MATCH(33,Dados!$O:$O,0)) -> 52.05516 | F42: =INDEX(Dados!$H:$H,MATCH(33,Dados!$O:$O,0)) -> 638.88889 | G42: =INDEX(Dados!$K:$K,MATCH(33,Dados!$O:$O,0)) -> 80 | H42: =INDEX(Dados!$L:$L,MATCH(33,Dados!$O:$O,0)) -> Alta | I42: =INDEX(Dados!$I:$I,MATCH(33,Dados!$O:$O,0)) -> Crescendo | J42: =INDEX(Dados!$F:$F,MATCH(33,Dados!$O:$O,0)) -> 2300000 | K42: =INDEX(Dados!$G:$G,MATCH(33,Dados!$O:$O,0)) -> 3600 | L42: =INDEX(Dados!$J:$J,MATCH(33,Dados!$O:$O,0)) -> 0.7057
...

Sheet Dados
A1: # | B1: Marca | C1: Posicionamento (classificação) | D1: Já no seu mix de nicho? | E1: Variação Ranking | F1: Vendas (R$) | G1: Unidades Vendidas | H1: Ticket Médio (R$) | I1: Tendência | J1: % Catálogo | K1: Nº Vendedores | L1: Saturação | M1: Ranking de Demanda (Nubmetrics) | N1: Pontuação (0-100) | O1: Rank Pontuação (auxiliar)
A2: 1 | B2: NATURA | C2: Nacional/Massa | D2: Não | E2: 1 | F2: 20900000 | G2: 161600 | H2: 129.33168 | I2: Estável | J2: 0.613 | K2: 549 | L2: Alta | M2: 23 | N2: =100*('Priorização de Entrada'!$B$3*(H2/MAX(H$2:H$101))+'Priorização de Entrada'!$B$4*(1-K2/MAX(K$2:K$101))+'Priorização de Entrada'!$B$5*(IF(L2="Baixa",1,IF(L2="Média",0.5,0)))+'Priorização de Entrada'!$B$6*(IF(I2="Crescendo",1,IF(I2="Estável",0.5,0)))) -> 18.403651 | O2: =SUMPRODUCT(($N$2:$N$101>N2)*1)+SUMPRODUCT(($N$2:N2=N2)*1) -> 98
A3: 2 | B3: LATTAFA | C3: Árabe/Import Acessível | D3: Não | E3: 1 | F3: 19000000 | G3: 99000 | H3: 191.91919 | I3: Estável | J3: 0.6514 | K3: 739 | L3: Média | M3: 0 | N3: =100*('Priorização de Entrada'!$B$3*(H3/MAX(H$2:H$101))+'Priorização de Entrada'!$B$4*(1-K3/MAX(K$2:K$101))+'Priorização de Entrada'!$B$5*(IF(L3="Baixa",1,IF(L3="Média",0.5,0)))+'Priorização de Entrada'!$B$6*(IF(I3="Crescendo",1,IF(I3="Estável",0.5,0)))) -> 22.932314 | O3: =SUMPRODUCT(($N$2:$N$101>N3)*1)+SUMPRODUCT(($N$2:N3=N3)*1) -> 96
A4: 3 | B4: O BOTICÁRIO | C4: Nacional/Massa | D4: Não | E4: -2 | F4: 19000000 | G4: 115100 | H4: 165.07385 | I4: Estável | J4: 0.632 | K4: 526 | L4: Média | M4: 17 | N4: =100*('Priorização de Entrada'!$B$3*(H4/MAX(H$2:H$101))+'Priorização de Entrada'!$B$4*(1-K4/MAX(K$2:K$101))+'Priorização de Entrada'!$B$5*(IF(L4="Baixa",1,IF(L4="Média",0.5,0)))+'Priorização de Entrada'!$B$6*(IF(I4="Crescendo",1,IF(I4="Estável",0.5,0)))) -> 29.72783 | O4: =SUMPRODUCT(($N$2:$N$101>N4)*1)+SUMPRODUCT(($N$2:N4=N4)*1) -> 78
A5: 4 | B5: CAROLINA HERRERA | C5: Designer/Importado | D5: Não | E5: 0 | F5: 10200000 | G5: 19500 | H5: 523.07692 | I5: Estável | J5: 0.6718 | K5: 29 | L5: Alta | M5: 0 | N5: =100*('Priorização de Entrada'!$B$3*(H5/MAX(H$2:H$101))+'Priorização de Entrada'!$B$4*(1-K5/MAX(K$2:K$101))+'Priorização de Entrada'!$B$5*(IF(L5="Baixa",1,IF(L5="Média",0.5,0)))+'Priorização de Entrada'!$B$6*(IF(I5="Crescendo",1,IF(I5="Estável",0.5,0)))) -> 42.010985 | O5: =SUMPRODUCT(($N$2:$N$101>N5)*1)+SUMPRODUCT(($N$2:N5=N5)*1) -> 56
A6: 5 | B6: ARMAF | C6: Árabe/Import Acessível | D6: Não | E6: 2 | F6: 8500000 | G6: 34800 | H6: 244.25287 | I6: Crescendo | J6: 0.6872 | K6: 264 | L6: Alta | M6: 0 | N6: =100*('Priorização de Entrada'!$B$3*(H6/MAX(H$2:H$101))+'Priorização de Entrada'!$B$4*(1-K6/MAX(K$2:K$101))+'Priorização de Entrada'!$B$5*(IF(L6="Baixa",1,IF(L6="Média",0.5,0)))+'Priorização de Entrada'!$B$6*(IF(I6="Crescendo",1,IF(I6="Estável",0.5,0)))) -> 39.800928 | O6: =SUMPRODUCT(($N$2:$N$101>N6)*1)+SUMPRODUCT(($N$2:N6=N6)*1) -> 60
A7: 6 | B7: AL WATANIAH | C7: Árabe/Import Acessível | D7: Não | E7: -1 | F7: 8300000 | G7: 61600 | H7: 134.74026 | I7: Diminuindo | J7: 0.6549 | K7: 431 | L7: Alta | M7: 0 | N7: =100*('Priorização de Entrada'!$B$3*(H7/MAX(H$2:H$101))+'Priorização de Entrada'!$B$4*(1-K7/MAX(K$2:K$101))+'Priorização de Entrada'!$B$5*(IF(L7="Baixa",1,IF(L7="Média",0.5,0)))+'Priorização de Entrada'!$B$6*(IF(I7="Crescendo",1,IF(I7="Estável",0.5,0)))) -> 12.478169 | O7: =SUMPRODUCT(($N$2:$N$101>N7)*1)+SUMPRODUCT(($N$2:N7=N7)*1) -> 100
A8: 7 | B8: RABANNE | C8: Designer/Importado | D8: Não | E8: -1 | F8: 8100000 | G8: 14100 | H8: 574.46809 | I8: Estável | J8: 0.6857 | K8: 32 | L8: Média | M8: 0 | N8: =100*('Priorização de Entrada'!$B$3*(H8/MAX(H$2:H$101))+'Priorização de Entrada'!$B$4*(1-K8/MAX(K$2:K$101))+'Priorização de Entrada'!$B$5*(IF(L8="Baixa",1,IF(L8="Média",0.5,0)))+'Priorização de Entrada'!$B$6*(IF(I8="Crescendo",1,IF(I8="Estável",0.5,0)))) -> 52.694697 | O8: =SUMPRODUCT(($N$2:$N$101>N8)*1)+SUMPRODUCT(($N$2:N8=N8)*1) -> 31
A9: 8 | B9: JEAN PAUL GAULTIER | C9: Designer/Importado | D9: Não | E9: 4 | F9: 4600000 | G9: 7200 | H9: 638.88889 | I9: Crescendo | J9: 0.7093 | K9: 27 | L9: Alta | M9: 46 | N9: =100*('Priorização de Entrada'!$B$3*(H9/MAX(H$2:H$101))+'Priorização de Entrada'!$B$4*(1-K9/MAX(K$2:K$101))+'Priorização de Entrada'!$B$5*(IF(L9="Baixa",1,IF(L9="Média",0.5,0)))+'Priorização de Entrada'!$B$6*(IF(I9="Crescendo",1,IF(I9="Estável",0.5,0)))) -> 53.848123 | O9: =SUMPRODUCT(($N$2:$N$101>N9)*1)+SUMPRODUCT(($N$2:N9=N9)*1) -> 27
A10: 9 | B10: MAISON ALHAMBRA | C10: Árabe/Import Acessível | D10: Não | E10: 0 | F10: 4400000 | G10: 27600 | H10: 159.42029 | I10: Estável | J10: 0.6829 | K10: 371 | L10: Média | M10: 0 | N10: =100*('Priorização de Entrada'!$B$3*(H10/MAX(H$2:H$101))+'Priorização de Entrada'!$B$4*(1-K10/MAX(K$2:K$101))+'Priorização de Entrada'!$B$5*(IF(L10="Baixa",1,IF(L10="Média",0.5,0)))+'Priorização de Entrada'!$B$6*(IF(I10="Crescendo",1,IF(I10="Estável",0.5,0)))) -> 34.885023 | O10: =SUMPRODUCT(($N$2:$N$101>N10)*1)+SUMPRODUCT(($N$2:N10=N10)*1) -> 71
A11: 10 | B11: LIPX | C11: A verificar | D11: Não | E11: 1 | F11: 4100000 | G11: 21000 | H11: 195.2381 | I11: Crescendo | J11: 0.8333 | K11: 36 | L11: Alta | M11: 0 | N11: =100*('Priorização de Entrada'!$B$3*(H11/MAX(H$2:H$101))+'Priorização de Entrada'!$B$4*(1-K11/MAX(K$2:K$101))+'Priorização de Entrada'!$B$5*(IF(L11="Baixa",1,IF(L11="Média",0.5,0)))+'Priorização de Entrada'!$B$6*(IF(I11="Crescendo",1,IF(I11="Estável",0.5,0)))) -> 46.765161 | O11: =SUMPRODUCT(($N$2:$N$101>N11)*1)+SUMPRODUCT(($N$2:N11=N11)*1) -> 38
A12: 11 | B12: EUDORA | C12: Nacional/Massa | D12: Não | E12: 2 | F12: 3900000 | G12: 39400 | H12: 98.984772 | I12: Crescendo | J12: 0.6278 | K12: 375 | L12: Alta | M12: 43 | N12: =100*('Priorização de Entrada'!$B$3*(H12/MAX(H$2:H$101))+'Priorização de Entrada'!$B$4*(1-K12/MAX(K$2:K$101))+'Priorização de Entrada'!$B$5*(IF(L12="Baixa",1,IF(L12="Média",0.5,0)))+'Priorização de Entrada'!$B$6*(IF(I12="Crescendo",1,IF(I12="Estável",0.5,0)))) -> 33.826316 | O12: =SUMPRODUCT(($N$2:$N$101>N12)*1)+SUMPRODUCT(($N$2:N12=N12)*1) -> 73
A13: 12 | B13: LANCÔME | C13: Designer/Importado Premium | D13: Não | E13: -4 | F13: 3700000 | G13: 7000 | H13: 528.57143 | I13: Diminuindo | J13: 0.5949 | K13: 6 | L13: Alta | M13: 0 | N13: =100*('Priorização de Entrada'!$B$3*(H13/MAX(H$2:H$101))+'Priorização de Entrada'!$B$4*(1-K13/MAX(K$2:K$101))+'Priorização de Entrada'!$B$5*(IF(L13="Baixa",1,IF(L13="Média",0.5,0)))+'Priorização de Entrada'!$B$6*(IF(I13="Crescendo",1,IF(I13="Estável",0.5,0)))) -> 32.873013 | O13: =SUMPRODUCT(($N$2:$N$101>N13)*1)+SUMPRODUCT(($N$2:N13=N13)*1) -> 76
... A101: 100 | B101: AL HARAMAIN | C101: Árabe/Import Acessível | D101: Não | E101: 7 | F101: 218100 | G101: 679 | H101: 321.20766 | I101: Crescendo | J101: 0.7247 | K101: 68 | L101: Baixa | M101: 0 | N101: =100*('Priorização de Entrada'!$B$3*(H101/MAX(H$2:H$101))+'Priorização de Entrada'!$B$4*(1-K101/MAX(K$2:K$101))+'Priorização de Entrada'!$B$5*(IF(L101="Baixa",1,IF(L101="Média",0.5,0)))+'Priorização de Entrada'!$B$6*(IF(I101="Crescendo",1,IF(I101="Estável",0.5,0)))) -> 67.607294 | O101: =SUMPRODUCT(($N$2:$N$101>N101)*1)+SUMPRODUCT(($N$2:N101=N101)*1) -> 8
